Workbook
Name Analysis_year: 'Project description'!$B$29
Name FinalYear_BC: Calculations!$B$3
Name FinalYear_PP: Calculations!$B$2
Name HurdleRateBasis: 'Project description'!$B$27
Name ReturnType: 'Project description'!$B$28
Name Start_Yr: 'Project description'!$B$10

Sheet Guidance
A2: This spreadsheet is for the applicant to fill in information about the 'Proposed project' (ie, the project for which Concenssions Loan funds are sought) and also a 'Base Case' (ie, the outcomes if the project were not to proceed).
A3: For example, the Proposed Project could be the replacement of a coal-fired boiler with a biomass boiler, whereas the Base Case could be the coal-fired boiler continuing to operate.
A5: The spreadsheet consists of two tabs:
A6: Project description in which basic information is input
A8: Project description. This has some input cells for applicants to fill in regarding the name and type of project,starting dates and the applicant's investment criteria.
A9: Inputs. This is the main tab for the applicant to fill in projected Capex and Opex cashflows for the Proposed Project and the Base Case, as well as projected fuel consumption for both situations.
A10: Scratch. This is a tab which applicants can use if they wish to do their own bespoke calculations - noting that the rest of the spreadsheet is 'locked-down' to enable EECA to extract and evaluate data in a rigorous fashion.

Sheet Project description
A1: Input data
A2: Project information | B2: Information should be included on the proposed project (assuming the loan is given) and the base case (what you would do without the loan)
A3: Field | B3: Value | C3: Notes
A4: ProjectID | B4: CL-001
A5: Applicant's name | B5: Oliver's Meatworks
A6: Sector | B6: Agriculture, Forestry and Fishing
A7: Region | B7: Gisborne
A8: Name for proposed project | B8: Heat pump gas replacement
A9: Date of application submission (dd/mm/yy) | B9: 45702
A10: First year of expenditure (yyyy) | B10: 2026
A11: Expected commissioning date of proposed project (dd/mm/yy) | B11: 46388
A13: Project type | B13: Early replacement of asset | C13: =IF(B13="Retrofit of existing asset","Project assumed to last only as long as the life of the existing asset","")
A14: =INDEX(Lists!$C$2:$C$5,MATCH(Lists!B6,Lists!$B$2:$B$5,0)) -> Expected final year of operation/use of existing asset if not replaced early | B14: 2035
A15: If not a retrofit, what is the expected economic or useful life of the new investment? | B15: 20 | C15: ="Final year = "&FinalYear_PP -> Final year = 2047
A16: =INDEX(Lists!E2:E5,MATCH(Lists!B6,Lists!$B$2:$B$5,0)) -> Without the loan, what would the existing asset be replaced with at the end of its life? | B16: The same as the the proposed project
A17: =INDEX(Lists!F2:F5,MATCH(Lists!B6,Lists!$B$2:$B$5,0)) -> What would be the expected life of the replacement asset in the base case (no loan) | B17: 20 | C17: ="Final year = "&FinalYear_BC -> Final year = 2047
A19: Does the project replace the use of coal for industrial process heat? | B19: No
A20: If this project replaces coal consumption for industrial process heat, does the project bring forward the time of replacement from the start of 2037? | B20: Yes | C20: =IF(AND(B20="Yes",B19="Yes"),"The base case used for analysis should be that of just meeting the regulated coal phase-out date of 2037","")
A21: Is this a heat pump project? | B21: Yes
A23: What level of loan contribution are you requesting? ($) | B23: 950000
A24: Start date? (dd/mm/yyyy) | B24: 45992
A25: How long would the loan be for? (years) | B25: 10 | C25: ="Full repayment by "&Start_Yr+B25 -> Full repayment by 2036
A26: What is your hurdle rate for this investment (%) | B26: 0.2
A27: What basis is used for the hurdle rate? | B27: Pre-tax Nominal
A28: Is the hurdle rate for the return on equity only or for the whole invstment | B28: Return on Equity
A29: Analysis year | B29: =YEAR(TODAY()) -> 2025

Sheet Inputs
A2: Inflation
A3: Cashflow values may be specified in real (ie, current year values) or nominal (values for the year of the cost or revenue item)
A4: ="All values for the current year ("&'Project description'!B29&") should be in current dollar values" -> All values for the current year (2025) should be in current dollar values
A5: I will include my own inflation assumptions | B5: No
A6: If an inflation rate has been used to produce a future nominal value, please note it below | G6: 2025 | H6: =G6+1 -> 2026 | I6: =H6+1 -> 2027 | J6: =I6+1 -> 2028 | K6: =J6+1 -> 2029 | L6: =K6+1 -> 2030 | M6: =L6+1 -> 2031 | N6: =M6+1 -> 2032 | O6: =N6+1 -> 2033 | ... AZ6: =AY6+1 -> 2070
A7: Inflation rate in the year | G7: 0.03 | H7: 0.02 | I7: 0.02 | J7: 0.02 | K7: 0.02 | L7: 0.02 | M7: 0.02 | N7: 0.02 | O7: 0.02 | P7: 0.02 | Q7: 0.02 | R7: 0.02 | S7: 0.02 | T7: 0.02 | U7: 0.02 | V7: 0.02 | W7: 0.02 | X7: 0.02 | Y7: 0.02 | Z7: 0.02 | AA7: 0.02 | AB7: 0.02 | AC7: 0.02 | AD7: 0.02 | AE7: 0.02 | AF7: 0.02 | AG7: =AF7 -> 0.02 | AH7: =AG7 -> 0.02 | AI7: =AH7 -> 0.02 | AJ7: =AI7 -> 0.02 | AK7: =AJ7 -> 0.02 | AL7: =AK7 -> 0.02 | AM7: =AL7 -> 0.02 | AN7: =AM7 -> 0.02 | ... AZ7: =AY7 -> 0.02
A8: Default inflation rates | G8: =Data!L33 -> 0.022 | H8: =Data!M33 -> 0.02 | I8: =Data!N33 -> 0.02 | J8: =Data!O33 -> 0.02 | K8: =Data!P33 -> 0.02 | L8: =Data!Q33 -> 0.02 | M8: =Data!R33 -> 0.02 | N8: =Data!S33 -> 0.02 | ... AZ8: =Data!BE33 -> 0.02
A9: Inflator - use this to convert real values to nominal | G9: 1 | H9: =G9*IF($B$5="Yes",(1+G7/2)*(1+H7/2),(1+G8/2)*(1+H8/2)) -> 1.02111 | I9: =H9*IF($B$5="Yes",(1+H7/2)*(1+I7/2),(1+H8/2)*(1+I8/2)) -> 1.0416343 | J9: =I9*IF($B$5="Yes",(1+I7/2)*(1+J7/2),(1+I8/2)*(1+J8/2)) -> 1.0625712 | K9: =J9*IF($B$5="Yes",(1+J7/2)*(1+K7/2),(1+J8/2)*(1+K8/2)) -> 1.0839288 | L9: =K9*IF($B$5="Yes",(1+K7/2)*(1+L7/2),(1+K8/2)*(1+L8/2)) -> 1.1057158 | M9: =L9*IF($B$5="Yes",(1+L7/2)*(1+M7/2),(1+L8/2)*(1+M8/2)) -> 1.1279407 | N9: =M9*IF($B$5="Yes",(1+M7/2)*(1+N7/2),(1+M8/2)*(1+N8/2)) -> 1.1506123 | O9: =N9*IF($B$5="Yes",(1+N7/2)*(1+O7/2),(1+N8/2)*(1+O8/2)) -> 1.1737396 | ... AZ9: =AY9*IF($B$5="Yes",(1+AY7/2)*(1+AZ7/2),(1+AY8/2)*(1+AZ8/2)) -> 2.4510571
A10: Deflator - use this to convert nominal values to real | G10: 1 | H10: =1/((1/G10)*IF($B$5="Yes",(1+G7/2)*(1+H7/2),(1+G8/2)*(1+H8/2))) -> 0.97932642 | I10: =1/((1/H10)*IF($B$5="Yes",(1+H7/2)*(1+I7/2),(1+H8/2)*(1+I8/2))) -> 0.96002982 | J10: =1/((1/I10)*IF($B$5="Yes",(1+I7/2)*(1+J7/2),(1+I8/2)*(1+J8/2))) -> 0.94111344 | K10: =1/((1/J10)*IF($B$5="Yes",(1+J7/2)*(1+K7/2),(1+J8/2)*(1+K8/2))) -> 0.92256979 | L10: =1/((1/K10)*IF($B$5="Yes",(1+K7/2)*(1+L7/2),(1+K8/2)*(1+L8/2))) -> 0.90439152 | M10: =1/((1/L10)*IF($B$5="Yes",(1+L7/2)*(1+M7/2),(1+L8/2)*(1+M8/2))) -> 0.88657143 | N10: =1/((1/M10)*IF($B$5="Yes",(1+M7/2)*(1+N7/2),(1+M8/2)*(1+N8/2))) -> 0.86910247 | O10: =1/((1/N10)*IF($B$5="Yes",(1+N7/2)*(1+O7/2),(1+N8/2)*(1+O8/2))) -> 0.85197772 | ... AZ10: =1/((1/AY10)*IF($B$5="Yes",(1+AY7/2)*(1+AZ7/2),(1+AY8/2)*(1+AZ8/2))) -> 0.40798724
A12: 1) Capital expenditure (CAPEX) ($) - please enter all costs as positive numbers
D13: Value basis | E13: Nominal
A14: Proposed Project (PP) | D14: Capex item | E14: Value basis | G14: Applicant comment | H14: 2026 | I14: 2027 | J14: 2028 | K14: 2029 | L14: 2030 | M14: 2031 | N14: 2032 | O14: 2033 | P14: 2034 | Q14: 2035 | R14: 2036 | S14: 2037 | T14: 2038 | U14: 2039 | V14: 2040 | W14: 2041 | X14: 2042 | Y14: 2043 | Z14: 2044 | AA14: 2045 | AB14: 2046 | AC14: 2047 | AD14: 2048 | AE14: 2049 | AF14: 2050 | AG14: 2051 | AH14: 2052 | AI14: 2053 | AJ14: 2054 | AK14: 2055 | AL14: 2056 | AM14: 2057 | AN14: 2058 | AO14: 2059 | AP14: 2060 | AQ14: 2061 | AR14: 2062 | AS14: 2063 | AT14: 2064 | AU14: 2065 | AV14: 2066 | AW14: 2067 | AX14: 2068 | AY14: 2069 | AZ14: 2070
A15: ="Please provide data through to "&FinalYear_PP -> Please provide data through to 2047 | D15: Equipment purchase | E15: =E$13 -> Nominal | H15: 800000 | I15: 800000
D16: Civil works | E16: =E$13 -> Nominal | H16: 80000
D17: Electrical works | E17: =E$13 -> Nominal | H17: 250000
D18: Installation | E18: =E$13 -> Nominal | H18: 100000
D19: Indirect costs | E19: =E$13 -> Nominal | H19: 50000 | I19: 50000
D20: Project management | E20: =E$13 -> Nominal
D21: Other | E21: =E$13 -> Nominal
D22: ="Total capex in "&Analysis_year&" dollars" -> Total capex in 2025 dollars | H22: =SUM(H15:H21)*IF($E$13="Real",1,H$10) -> 1253537.8 | I22: =SUM(I15:I21)*IF($E$13="Real",1,I$10) -> 816025.35 | J22: =SUM(J15:J21)*IF($E$13="Real",1,J$10) -> 0 | K22: =SUM(K15:K21)*IF($E$13="Real",1,K$10) -> 0 | L22: =SUM(L15:L21)*IF($E$13="Real",1,L$10) -> 0 | M22: =SUM(M15:M21)*IF($E$13="Real",1,M$10) -> 0 | N22: =SUM(N15:N21)*IF($E$13="Real",1,N$10) -> 0 | O22: =SUM(O15:O21)*IF($E$13="Real",1,O$10) -> 0 | ... AZ22: =SUM(AZ15:AZ21)*IF($E$13="Real",1,AZ$10) -> 0
D23: Total capex in nominal dollars | H23: =SUM(H15:H21)*IF($E$13="Real",H9,1) -> 1280000 | I23: =SUM(I15:I21)*IF($E$13="Real",I9,1) -> 850000 | J23: =SUM(J15:J21)*IF($E$13="Real",J9,1) -> 0 | K23: =SUM(K15:K21)*IF($E$13="Real",K9,1) -> 0 | L23: =SUM(L15:L21)*IF($E$13="Real",L9,1) -> 0 | M23: =SUM(M15:M21)*IF($E$13="Real",M9,1) -> 0 | N23: =SUM(N15:N21)*IF($E$13="Real",N9,1) -> 0 | O23: =SUM(O15:O21)*IF($E$13="Real",O9,1) -> 0 | ... AZ23: =SUM(AZ15:AZ21)*IF($E$13="Real",AZ9,1) -> 0
D25: Value basis | E25: Nominal
A26: Base Case (BC) | D26: Capex item | E26: Value basis | G26: Applicant comment | H26: 2026 | I26: 2027 | J26: 2028 | K26: 2029 | L26: 2030 | M26: 2031 | N26: 2032 | O26: 2033 | P26: 2034 | Q26: 2035 | R26: 2036 | S26: 2037 | T26: 2038 | U26: 2039 | V26: 2040 | W26: 2041 | X26: 2042 | Y26: 2043 | Z26: 2044 | AA26: 2045 | AB26: 2046 | AC26: 2047 | AD26: 2048 | AE26: 2049 | AF26: 2050 | AG26: 2051 | AH26: 2052 | AI26: 2053 | AJ26: 2054 | AK26: 2055 | AL26: 2056 | AM26: 2057 | AN26: 2058 | AO26: 2059 | AP26: 2060 | AQ26: 2061 | AR26: 2062 | AS26: 2063 | AT26: 2064 | AU26: 2065 | AV26: 2066 | AW26: 2067 | AX26: 2068 | AY26: 2069 | AZ26: 2070
A27: Expand if more items | D27: Equipment purchase | E27: =$E$25 -> Nominal | H27: 0 | I27: 0
D28: Civil works | E28: =$E$25 -> Nominal
D29: Electrical works | E29: =$E$25 -> Nominal
D30: Installation | E30: =$E$25 -> Nominal
D31: Indirect costs | E31: =$E$25 -> Nominal
D32: Project management | E32: =$E$25 -> Nominal
D33: Other | E33: =$E$25 -> Nominal
D34: ="Total capex in "&Analysis_year&" dollars" -> Total capex in 2025 dollars | H34: =SUM(H27:H33)*IF($E$25="Real",1,H$10) -> 0 | I34: =SUM(I27:I33)*IF($E$25="Real",1,I$10) -> 0 | J34: =SUM(J27:J33)*IF($E$25="Real",1,J$10) -> 0 | K34: =SUM(K27:K33)*IF($E$25="Real",1,K$10) -> 0 | L34: =SUM(L27:L33)*IF($E$25="Real",1,L$10) -> 0 | M34: =SUM(M27:M33)*IF($E$25="Real",1,M$10) -> 0 | N34: =SUM(N27:N33)*IF($E$25="Real",1,N$10) -> 0 | O34: =SUM(O27:O33)*IF($E$25="Real",1,O$10) -> 0 | ... AZ34: =SUM(AZ27:AZ33)*IF($E$25="Real",1,AZ$10) -> 0
D35: Total capex in nominal dollars | H35: =SUM(H27:H33)*IF($E$25="Real",H$9,1) -> 0 | I35: =SUM(I27:I33)*IF($E$25="Real",I$9,1) -> 0 | J35: =SUM(J27:J33)*IF($E$25="Real",J$9,1) -> 0 | K35: =SUM(K27:K33)*IF($E$25="Real",K$9,1) -> 0 | L35: =SUM(L27:L33)*IF($E$25="Real",L$9,1) -> 0 | M35: =SUM(M27:M33)*IF($E$25="Real",M$9,1) -> 0 | N35: =SUM(N27:N33)*IF($E$25="Real",N$9,1) -> 0 | O35: =SUM(O27:O33)*IF($E$25="Real",O$9,1) -> 0 | ... AZ35: =SUM(AZ27:AZ33)*IF($E$25="Real",AZ$9,1) -> 0
A38: 2) Operating & Maintenance Expenditure (OPEX) ($) - please enter all costs as positive numbers
A39: 2a) Non-fuel opex | D39: Value basis | E39: nominal
A40: Proposed Project (PP) | D40: Opex item | E40: Value basis | G40: Applicant comment | H40: 2026 | I40: 2027 | J40: 2028 | K40: 2029 | L40: 2030 | M40: 2031 | N40: 2032 | O40: 2033 | P40: 2034 | Q40: 2035 | R40: 2036 | S40: 2037 | T40: 2038 | U40: 2039 | V40: 2040 | W40: 2041 | X40: 2042 | Y40: 2043 | Z40: 2044 | AA40: 2045 | AB40: 2046 | AC40: 2047 | AD40: 2048 | AE40: 2049 | AF40: 2050 | AG40: 2051 | AH40: 2052 | AI40: 2053 | AJ40: 2054 | AK40: 2055 | AL40: 2056 | AM40: 2057 | AN40: 2058 | AO40: 2059 | AP40: 2060 | AQ40: 2061 | AR40: 2062 | AS40: 2063 | AT40: 2064 | AU40: 2065 | AV40: 2066 | AW40: 2067 | AX40: 2068 | AY40: 2069 | AZ40: 2070
A41: ="Please provide data through to "&FinalYear_PP -> Please provide data through to 2047 | D41: Energy costs (already handled separately) | E41: =$E$39 -> nominal
D42: Equipment Operation Costs | E42: =$E$39 -> nominal | H42: 100000 | I42: =H42 -> 100000 | J42: =I42 -> 100000 | K42: =J42 -> 100000 | L42: =K42 -> 100000 | M42: =L42 -> 100000 | N42: =M42 -> 100000 | O42: =N42 -> 100000 | P42: =O42 -> 100000 | ... AC42: =AB42 -> 100000
D43: Maintenance, Repairs, Inspections | E43: =$E$39 -> nominal | H43: 20000 | I43: 20000 | J43: 20000 | K43: 20000 | L43: 20000 | M43: 20000 | N43: 20000 | O43: 20000 | P43: 20000 | Q43: 20000 | R43: 20000 | S43: 20000 | T43: 20000 | U43: 20000 | V43: 20000 | W43: 20000 | X43: 20000 | Y43: 20000 | Z43: 20000 | AA43: 20000 | AB43: 20000 | AC43: 20000
D44: Compliance Testing | E44: =$E$39 -> nominal | H44: 10000 | I44: 10000
D45: Optimisation | E45: =$E$39 -> nominal
...

Sheet Scratch
A3: Base | F3: Heat demand (GJ) | K3: Project
A5: Annual gas (GJ) | B5: 70000 | F5: =B5*B15 -> 56000 | K5: Annual electricity for same work (GJ) | L5: =F5/B14 -> 16000
A6: Annual electricity (mWh) | B6: 120 | K6: mWh conversion | L6: =L5*B18 -> 4444.448
K7: Demand growth (rebound) | L7: 1.1
K9: New electricity demand (mWh) | L9: =(L6*L7)+B6 -> 5008.8928
A14: COP of heat pump | B14: 3.5
A15: Efficiency of gas | B15: =0.8 -> 0.8
A18: GJ to MWH conversion | B18: =0.277778 -> 0.277778

Sheet Real values
A2: Financial projection basis
A4: Inflator - use this to convert real values to nominal | G4: =Inputs!G9 -> 1 | H4: =Inputs!H9 -> 1.02111 | I4: =Inputs!I9 -> 1.0416343 | J4: =Inputs!J9 -> 1.0625712 | K4: =Inputs!K9 -> 1.0839288 | L4: =Inputs!L9 -> 1.1057158 | M4: =Inputs!M9 -> 1.1279407 | N4: =Inputs!N9 -> 1.1506123 | ... AZ4: =Inputs!AZ9 -> 2.4510571
A5: Deflator - use this to convert nominal values to real | G5: =Inputs!G10 -> 1 | H5: =Inputs!H10 -> 0.97932642 | I5: =Inputs!I10 -> 0.96002982 | J5: =Inputs!J10 -> 0.94111344 | K5: =Inputs!K10 -> 0.92256979 | L5: =Inputs!L10 -> 0.90439152 | M5: =Inputs!M10 -> 0.88657143 | N5: =Inputs!N10 -> 0.86910247 | ... AZ5: =Inputs!AZ10 -> 0.40798724
A7: 1) Capital expenditure (CAPEX) ($) - please enter all costs as positive numbers
A9: Proposed Project (PP) | D9: Capex item | E9: Value basis | F9: Base year | G9: Applicant comment | H9: 2026 | I9: 2027 | J9: 2028 | K9: 2029 | L9: 2030 | M9: 2031 | N9: 2032 | O9: 2033 | P9: 2034 | Q9: 2035 | R9: 2036 | S9: 2037 | T9: 2038 | U9: 2039 | V9: 2040 | W9: 2041 | X9: 2042 | Y9: 2043 | Z9: 2044 | AA9: 2045 | AB9: 2046 | AC9: 2047 | AD9: 2048 | AE9: 2049 | AF9: 2050 | AG9: 2051 | AH9: 2052 | AI9: 2053 | AJ9: 2054 | AK9: 2055 | AL9: 2056 | AM9: 2057 | AN9: 2058 | AO9: 2059 | AP9: 2060 | AQ9: 2061 | AR9: 2062 | AS9: 2063 | AT9: 2064 | AU9: 2065 | AV9: 2066 | AW9: 2067 | AX9: 2068 | AY9: 2069 | AZ9: 2070
D10: Equipment purchase | E10: Real | F10: =Analysis_year -> 2025 | G10: =Inputs!G15 -> 0 | H10: =Inputs!H15*IF(Inputs!$E15="Real",1,H$5) -> 783461.14 | I10: =Inputs!I15*IF(Inputs!$E15="Real",1,I$5) -> 768023.86 | J10: =Inputs!J15*IF(Inputs!$E15="Real",1,J$5) -> 0 | K10: =Inputs!K15*IF(Inputs!$E15="Real",1,K$5) -> 0 | L10: =Inputs!L15*IF(Inputs!$E15="Real",1,L$5) -> 0 | M10: =Inputs!M15*IF(Inputs!$E15="Real",1,M$5) -> 0 | N10: =Inputs!N15*IF(Inputs!$E15="Real",1,N$5) -> 0 | O10: =Inputs!O15*IF(Inputs!$E15="Real",1,O$5) -> 0 | ... AZ10: =Inputs!AZ15*IF(Inputs!$E15="Real",1,AZ$5) -> 0
D11: Civil works | E11: Real | F11: =Analysis_year -> 2025 | G11: =Inputs!G16 -> 0 | H11: =Inputs!H16*IF(Inputs!$E16="Real",1,H$5) -> 78346.114 | I11: =Inputs!I16*IF(Inputs!$E16="Real",1,I$5) -> 0 | J11: =Inputs!J16*IF(Inputs!$E16="Real",1,J$5) -> 0 | K11: =Inputs!K16*IF(Inputs!$E16="Real",1,K$5) -> 0 | L11: =Inputs!L16*IF(Inputs!$E16="Real",1,L$5) -> 0 | M11: =Inputs!M16*IF(Inputs!$E16="Real",1,M$5) -> 0 | N11: =Inputs!N16*IF(Inputs!$E16="Real",1,N$5) -> 0 | O11: =Inputs!O16*IF(Inputs!$E16="Real",1,O$5) -> 0 | ... AZ11: =Inputs!AZ16*IF(Inputs!$E16="Real",1,AZ$5) -> 0
D12: Electrical works | E12: Real | F12: =Analysis_year -> 2025 | G12: =Inputs!G17 -> 0 | H12: =Inputs!H17*IF(Inputs!$E17="Real",1,H$5) -> 244831.6 | I12: =Inputs!I17*IF(Inputs!$E17="Real",1,I$5) -> 0 | J12: =Inputs!J17*IF(Inputs!$E17="Real",1,J$5) -> 0 | K12: =Inputs!K17*IF(Inputs!$E17="Real",1,K$5) -> 0 | L12: =Inputs!L17*IF(Inputs!$E17="Real",1,L$5) -> 0 | M12: =Inputs!M17*IF(Inputs!$E17="Real",1,M$5) -> 0 | N12: =Inputs!N17*IF(Inputs!$E17="Real",1,N$5) -> 0 | O12: =Inputs!O17*IF(Inputs!$E17="Real",1,O$5) -> 0 | ... AZ12: =Inputs!AZ17*IF(Inputs!$E17="Real",1,AZ$5) -> 0
D13: Installation | E13: Real | F13: =Analysis_year -> 2025 | G13: =Inputs!G18 -> 0 | H13: =Inputs!H18*IF(Inputs!$E18="Real",1,H$5) -> 97932.642 | I13: =Inputs!I18*IF(Inputs!$E18="Real",1,I$5) -> 0 | J13: =Inputs!J18*IF(Inputs!$E18="Real",1,J$5) -> 0 | K13: =Inputs!K18*IF(Inputs!$E18="Real",1,K$5) -> 0 | L13: =Inputs!L18*IF(Inputs!$E18="Real",1,L$5) -> 0 | M13: =Inputs!M18*IF(Inputs!$E18="Real",1,M$5) -> 0 | N13: =Inputs!N18*IF(Inputs!$E18="Real",1,N$5) -> 0 | O13: =Inputs!O18*IF(Inputs!$E18="Real",1,O$5) -> 0 | ... AZ13: =Inputs!AZ18*IF(Inputs!$E18="Real",1,AZ$5) -> 0
D14: Indirect costs | E14: Real | F14: =Analysis_year -> 2025 | G14: =Inputs!G19 -> 0 | H14: =Inputs!H19*IF(Inputs!$E19="Real",1,H$5) -> 48966.321 | I14: =Inputs!I19*IF(Inputs!$E19="Real",1,I$5) -> 48001.491 | J14: =Inputs!J19*IF(Inputs!$E19="Real",1,J$5) -> 0 | K14: =Inputs!K19*IF(Inputs!$E19="Real",1,K$5) -> 0 | L14: =Inputs!L19*IF(Inputs!$E19="Real",1,L$5) -> 0 | M14: =Inputs!M19*IF(Inputs!$E19="Real",1,M$5) -> 0 | N14: =Inputs!N19*IF(Inputs!$E19="Real",1,N$5) -> 0 | O14: =Inputs!O19*IF(Inputs!$E19="Real",1,O$5) -> 0 | ... AZ14: =Inputs!AZ19*IF(Inputs!$E19="Real",1,AZ$5) -> 0
D15: Project management | E15: Real | F15: =Analysis_year -> 2025 | G15: =Inputs!G20 -> 0 | H15: =Inputs!H20*IF(Inputs!$E20="Real",1,H$5) -> 0 | I15: =Inputs!I20*IF(Inputs!$E20="Real",1,I$5) -> 0 | J15: =Inputs!J20*IF(Inputs!$E20="Real",1,J$5) -> 0 | K15: =Inputs!K20*IF(Inputs!$E20="Real",1,K$5) -> 0 | L15: =Inputs!L20*IF(Inputs!$E20="Real",1,L$5) -> 0 | M15: =Inputs!M20*IF(Inputs!$E20="Real",1,M$5) -> 0 | N15: =Inputs!N20*IF(Inputs!$E20="Real",1,N$5) -> 0 | O15: =Inputs!O20*IF(Inputs!$E20="Real",1,O$5) -> 0 | ... AZ15: =Inputs!AZ20*IF(Inputs!$E20="Real",1,AZ$5) -> 0
D16: Other | E16: Real | F16: =Analysis_year -> 2025 | G16: =Inputs!G21 -> 0 | H16: =Inputs!H21*IF(Inputs!$E21="Real",1,H$5) -> 0 | I16: =Inputs!I21*IF(Inputs!$E21="Real",1,I$5) -> 0 | J16: =Inputs!J21*IF(Inputs!$E21="Real",1,J$5) -> 0 | K16: =Inputs!K21*IF(Inputs!$E21="Real",1,K$5) -> 0 | L16: =Inputs!L21*IF(Inputs!$E21="Real",1,L$5) -> 0 | M16: =Inputs!M21*IF(Inputs!$E21="Real",1,M$5) -> 0 | N16: =Inputs!N21*IF(Inputs!$E21="Real",1,N$5) -> 0 | O16: =Inputs!O21*IF(Inputs!$E21="Real",1,O$5) -> 0 | ... AZ16: =Inputs!AZ21*IF(Inputs!$E21="Real",1,AZ$5) -> 0
D17: ="Total capex in "&Analysis_year&" dollars" -> Total capex in 2025 dollars | H17: =SUBTOTAL(109,Capex_PP[2026]) -> 1253537.8 | I17: =SUM(I10:I16)*IF($E$8="Real",1,I$5) -> 783408.67 | J17: =SUM(J10:J16)*IF($E$8="Real",1,J$5) -> 0 | K17: =SUM(K10:K16)*IF($E$8="Real",1,K$5) -> 0 | L17: =SUM(L10:L16)*IF($E$8="Real",1,L$5) -> 0 | M17: =SUM(M10:M16)*IF($E$8="Real",1,M$5) -> 0 | N17: =SUM(N10:N16)*IF($E$8="Real",1,N$5) -> 0 | O17: =SUM(O10:O16)*IF($E$8="Real",1,O$5) -> 0 | P17: =SUM(P10:P16)*IF($E$8="Real",1,P$5) -> 0 | ... AZ17: =SUM(AZ10:AZ16)*IF($E$8="Real",1,AZ$5) -> 0
A19: Base Case (BC) | D19: Capex item | E19: Value basis | F19: Base year | G19: Applicant comment | H19: 2026 | I19: 2027 | J19: 2028 | K19: 2029 | L19: 2030 | M19: 2031 | N19: 2032 | O19: 2033 | P19: 2034 | Q19: 2035 | R19: 2036 | S19: 2037 | T19: 2038 | U19: 2039 | V19: 2040 | W19: 2041 | X19: 2042 | Y19: 2043 | Z19: 2044 | AA19: 2045 | AB19: 2046 | AC19: 2047 | AD19: 2048 | AE19: 2049 | AF19: 2050 | AG19: 2051 | AH19: 2052 | AI19: 2053 | AJ19: 2054 | AK19: 2055 | AL19: 2056 | AM19: 2057 | AN19: 2058 | AO19: 2059 | AP19: 2060 | AQ19: 2061 | AR19: 2062 | AS19: 2063 | AT19: 2064 | AU19: 2065 | AV19: 2066 | AW19: 2067 | AX19: 2068 | AY19: 2069 | AZ19: 2070
A20: Expand if more items | D20: Equipment purchase | E20: Real | F20: =Analysis_year -> 2025 | G20: =Inputs!G27 -> 0 | H20: =Inputs!H27*IF(Inputs!$E27="Real",1,H$5) -> 0 | I20: =Inputs!I27*IF(Inputs!$E27="Real",1,I$5) -> 0 | J20: =Inputs!J27*IF(Inputs!$E27="Real",1,J$5) -> 0 | K20: =Inputs!K27*IF(Inputs!$E27="Real",1,K$5) -> 0 | L20: =Inputs!L27*IF(Inputs!$E27="Real",1,L$5) -> 0 | M20: =Inputs!M27*IF(Inputs!$E27="Real",1,M$5) -> 0 | N20: =Inputs!N27*IF(Inputs!$E27="Real",1,N$5) -> 0 | O20: =Inputs!O27*IF(Inputs!$E27="Real",1,O$5) -> 0 | ... AZ20: =Inputs!AZ27*IF(Inputs!$E27="Real",1,AZ$5) -> 0
D21: Civil works | E21: Real | F21: =Analysis_year -> 2025 | G21: =Inputs!G28 -> 0 | H21: =Inputs!H28*IF(Inputs!$E28="Real",1,H$5) -> 0 | I21: =Inputs!I28*IF(Inputs!$E28="Real",1,I$5) -> 0 | J21: =Inputs!J28*IF(Inputs!$E28="Real",1,J$5) -> 0 | K21: =Inputs!K28*IF(Inputs!$E28="Real",1,K$5) -> 0 | L21: =Inputs!L28*IF(Inputs!$E28="Real",1,L$5) -> 0 | M21: =Inputs!M28*IF(Inputs!$E28="Real",1,M$5) -> 0 | N21: =Inputs!N28*IF(Inputs!$E28="Real",1,N$5) -> 0 | O21: =Inputs!O28*IF(Inputs!$E28="Real",1,O$5) -> 0 | ... AZ21: =Inputs!AZ28*IF(Inputs!$E28="Real",1,AZ$5) -> 0
D22: Electrical works | E22: Real | F22: =Analysis_year -> 2025 | G22: =Inputs!G29 -> 0 | H22: =Inputs!H29*IF(Inputs!$E29="Real",1,H$5) -> 0 | I22: =Inputs!I29*IF(Inputs!$E29="Real",1,I$5) -> 0 | J22: =Inputs!J29*IF(Inputs!$E29="Real",1,J$5) -> 0 | K22: =Inputs!K29*IF(Inputs!$E29="Real",1,K$5) -> 0 | L22: =Inputs!L29*IF(Inputs!$E29="Real",1,L$5) -> 0 | M22: =Inputs!M29*IF(Inputs!$E29="Real",1,M$5) -> 0 | N22: =Inputs!N29*IF(Inputs!$E29="Real",1,N$5) -> 0 | O22: =Inputs!O29*IF(Inputs!$E29="Real",1,O$5) -> 0 | ... AZ22: =Inputs!AZ29*IF(Inputs!$E29="Real",1,AZ$5) -> 0
D23: Installation | E23: Real | F23: =Analysis_year -> 2025 | G23: =Inputs!G30 -> 0 | H23: =Inputs!H30*IF(Inputs!$E30="Real",1,H$5) -> 0 | I23: =Inputs!I30*IF(Inputs!$E30="Real",1,I$5) -> 0 | J23: =Inputs!J30*IF(Inputs!$E30="Real",1,J$5) -> 0 | K23: =Inputs!K30*IF(Inputs!$E30="Real",1,K$5) -> 0 | L23: =Inputs!L30*IF(Inputs!$E30="Real",1,L$5) -> 0 | M23: =Inputs!M30*IF(Inputs!$E30="Real",1,M$5) -> 0 | N23: =Inputs!N30*IF(Inputs!$E30="Real",1,N$5) -> 0 | O23: =Inputs!O30*IF(Inputs!$E30="Real",1,O$5) -> 0 | ... AZ23: =Inputs!AZ30*IF(Inputs!$E30="Real",1,AZ$5) -> 0
D24: Indirect costs | E24: Real | F24: =Analysis_year -> 2025 | G24: =Inputs!G31 -> 0 | H24: =Inputs!H31*IF(Inputs!$E31="Real",1,H$5) -> 0 | I24: =Inputs!I31*IF(Inputs!$E31="Real",1,I$5) -> 0 | J24: =Inputs!J31*IF(Inputs!$E31="Real",1,J$5) -> 0 | K24: =Inputs!K31*IF(Inputs!$E31="Real",1,K$5) -> 0 | L24: =Inputs!L31*IF(Inputs!$E31="Real",1,L$5) -> 0 | M24: =Inputs!M31*IF(Inputs!$E31="Real",1,M$5) -> 0 | N24: =Inputs!N31*IF(Inputs!$E31="Real",1,N$5) -> 0 | O24: =Inputs!O31*IF(Inputs!$E31="Real",1,O$5) -> 0 | ... AZ24: =Inputs!AZ31*IF(Inputs!$E31="Real",1,AZ$5) -> 0
D25: Project management | E25: Real | F25: =Analysis_year -> 2025 | G25: =Inputs!G32 -> 0 | H25: =Inputs!H32*IF(Inputs!$E32="Real",1,H$5) -> 0 | I25: =Inputs!I32*IF(Inputs!$E32="Real",1,I$5) -> 0 | J25: =Inputs!J32*IF(Inputs!$E32="Real",1,J$5) -> 0 | K25: =Inputs!K32*IF(Inputs!$E32="Real",1,K$5) -> 0 | L25: =Inputs!L32*IF(Inputs!$E32="Real",1,L$5) -> 0 | M25: =Inputs!M32*IF(Inputs!$E32="Real",1,M$5) -> 0 | N25: =Inputs!N32*IF(Inputs!$E32="Real",1,N$5) -> 0 | O25: =Inputs!O32*IF(Inputs!$E32="Real",1,O$5) -> 0 | ... AZ25: =Inputs!AZ32*IF(Inputs!$E32="Real",1,AZ$5) -> 0
D26: Other | E26: Real | F26: =Analysis_year -> 2025 | G26: =Inputs!G33 -> 0 | H26: =Inputs!H33*IF(Inputs!$E33="Real",1,H$5) -> 0 | I26: =Inputs!I33*IF(Inputs!$E33="Real",1,I$5) -> 0 | J26: =Inputs!J33*IF(Inputs!$E33="Real",1,J$5) -> 0 | K26: =Inputs!K33*IF(Inputs!$E33="Real",1,K$5) -> 0 | L26: =Inputs!L33*IF(Inputs!$E33="Real",1,L$5) -> 0 | M26: =Inputs!M33*IF(Inputs!$E33="Real",1,M$5) -> 0 | N26: =Inputs!N33*IF(Inputs!$E33="Real",1,N$5) -> 0 | O26: =Inputs!O33*IF(Inputs!$E33="Real",1,O$5) -> 0 | ... AZ26: =Inputs!AZ33*IF(Inputs!$E33="Real",1,AZ$5) -> 0
D27: ="Total capex in "&Analysis_year&" dollars" -> Total capex in 2025 dollars | H27: =SUBTOTAL(109,Capex_BC[2026]) -> 0 | I27: =SUBTOTAL(109,Capex_BC[2027]) -> 0 | J27: =SUBTOTAL(109,Capex_BC[2028]) -> 0 | K27: =SUBTOTAL(109,Capex_BC[2029]) -> 0 | L27: =SUBTOTAL(109,Capex_BC[2030]) -> 0 | M27: =SUBTOTAL(109,Capex_BC[2031]) -> 0 | N27: =SUBTOTAL(109,Capex_BC[2032]) -> 0 | O27: =SUBTOTAL(109,Capex_BC[2033]) -> 0 | P27: =SUBTOTAL(109,Capex_BC[2034]) -> 0 | Q27: =SUBTOTAL(109,Capex_BC[2035]) -> 0 | R27: =SUBTOTAL(109,Capex_BC[2036]) -> 0 | S27: =SUBTOTAL(109,Capex_BC[2037]) -> 0 | T27: =SUBTOTAL(109,Capex_BC[2038]) -> 0 | U27: =SUBTOTAL(109,Capex_BC[2039]) -> 0 | V27: =SUBTOTAL(109,Capex_BC[2040]) -> 0 | W27: =SUBTOTAL(109,Capex_BC[2041]) -> 0 | X27: =SUBTOTAL(109,Capex_BC[2042]) -> 0 | Y27: =SUBTOTAL(109,Capex_BC[2043]) -> 0 | Z27: =SUBTOTAL(109,Capex_BC[2044]) -> 0 | AA27: =SUBTOTAL(109,Capex_BC[2045]) -> 0 | AB27: =SUBTOTAL(109,Capex_BC[2046]) -> 0 | AC27: =SUBTOTAL(109,Capex_BC[2047]) -> 0 | AD27: =SUBTOTAL(109,Capex_BC[2048]) -> 0 | AE27: =SUBTOTAL(109,Capex_BC[2049]) -> 0 | AF27: =SUBTOTAL(109,Capex_BC[2050]) -> 0 | AG27: =SUBTOTAL(109,Capex_BC[2051]) -> 0 | AH27: =SUBTOTAL(109,Capex_BC[2052]) -> 0 | AI27: =SUBTOTAL(109,Capex_BC[2053]) -> 0 | AJ27: =SUBTOTAL(109,Capex_BC[2054]) -> 0 | AK27: =SUBTOTAL(109,Capex_BC[2055]) -> 0 | AL27: =SUBTOTAL(109,Capex_BC[2056]) -> 0 | AM27: =SUBTOTAL(109,Capex_BC[2057]) -> 0 | AN27: =SUBTOTAL(109,Capex_BC[2058]) -> 0 | AO27: =SUBTOTAL(109,Capex_BC[2059]) -> 0 | AP27: =SUBTOTAL(109,Capex_BC[2060]) -> 0 | AQ27: =SUBTOTAL(109,Capex_BC[2061]) -> 0 | AR27: =SUBTOTAL(109,Capex_BC[2062]) -> 0 | AS27: =SUBTOTAL(109,Capex_BC[2063]) -> 0 | AT27: =SUBTOTAL(109,Capex_BC[2064]) -> 0 | AU27: =SUBTOTAL(109,Capex_BC[2065]) -> 0 | AV27: =SUBTOTAL(109,Capex_BC[2066]) -> 0 | AW27: =SUBTOTAL(109,Capex_BC[2067]) -> 0 | AX27: =SUBTOTAL(109,Capex_BC[2068]) -> 0 | AY27: =SUBTOTAL(109,Capex_BC[2069]) -> 0 | AZ27: =SUBTOTAL(109,Capex_BC[2070]) -> 0
A29: 2) Operating & Maintenance Expenditure (OPEX) ($) - please enter all costs as positive numbers
A30: 2a) Non-fuel opex
A31: Proposed Project (PP) | D31: Opex item | E31: Value basis | F31: Base year | G31: Applicant comment | H31: 2026 | I31: 2027 | J31: 2028 | K31: 2029 | L31: 2030 | M31: 2031 | N31: 2032 | O31: 2033 | P31: 2034 | Q31: 2035 | R31: 2036 | S31: 2037 | T31: 2038 | U31: 2039 | V31: 2040 | W31: 2041 | X31: 2042 | Y31: 2043 | Z31: 2044 | AA31: 2045 | AB31: 2046 | AC31: 2047 | AD31: 2048 | AE31: 2049 | AF31: 2050 | AG31: 2051 | AH31: 2052 | AI31: 2053 | AJ31: 2054 | AK31: 2055 | AL31: 2056 | AM31: 2057 | AN31: 2058 | AO31: 2059 | AP31: 2060 | AQ31: 2061 | AR31: 2062 | AS31: 2063 | AT31: 2064 | AU31: 2065 | AV31: 2066 | AW31: 2067 | AX31: 2068 | AY31: 2069 | AZ31: 2070
D32: Energy costs (already handled separately) | E32: Real | F32: =Analysis_year -> 2025 | G32: =Inputs!G41 -> 0 | H32: =Inputs!H41*IF(Inputs!$E41="Real",1,H$5) -> 0 | I32: =Inputs!I41*IF(Inputs!$E41="Real",1,I$5) -> 0 | J32: =Inputs!J41*IF(Inputs!$E41="Real",1,J$5) -> 0 | K32: =Inputs!K41*IF(Inputs!$E41="Real",1,K$5) -> 0 | L32: =Inputs!L41*IF(Inputs!$E41="Real",1,L$5) -> 0 | M32: =Inputs!M41*IF(Inputs!$E41="Real",1,M$5) -> 0 | N32: =Inputs!N41*IF(Inputs!$E41="Real",1,N$5) -> 0 | O32: =Inputs!O41*IF(Inputs!$E41="Real",1,O$5) -> 0 | ... AZ32: =Inputs!AZ41*IF(Inputs!$E41="Real",1,AZ$5) -> 0
D33: Equipment Operation Costs | E33: Real | F33: =Analysis_year -> 2025 | G33: =Inputs!G42 -> 0 | H33: =Inputs!H42*IF(Inputs!$E42="Real",1,H$5) -> 97932.642 | I33: =Inputs!I42*IF(Inputs!$E42="Real",1,I$5) -> 96002.982 | J33: =Inputs!J42*IF(Inputs!$E42="Real",1,J$5) -> 94111.344 | K33: =Inputs!K42*IF(Inputs!$E42="Real",1,K$5) -> 92256.979 | L33: =Inputs!L42*IF(Inputs!$E42="Real",1,L$5) -> 90439.152 | M33: =Inputs!M42*IF(Inputs!$E42="Real",1,M$5) -> 88657.143 | N33: =Inputs!N42*IF(Inputs!$E42="Real",1,N$5) -> 86910.247 | O33: =Inputs!O42*IF(Inputs!$E42="Real",1,O$5) -> 85197.772 | ... AZ33: =Inputs!AZ42*IF(Inputs!$E42="Real",1,AZ$5) -> 0
D34: Maintenance, Repairs, Inspections | E34: Real | F34: =Analysis_year -> 2025 | G34: =Inputs!G43 -> 0 | H34: =Inputs!H43*IF(Inputs!$E43="Real",1,H$5) -> 19586.528 | I34: =Inputs!I43*IF(Inputs!$E43="Real",1,I$5) -> 19200.596 | J34: =Inputs!J43*IF(Inputs!$E43="Real",1,J$5) -> 18822.269 | K34: =Inputs!K43*IF(Inputs!$E43="Real",1,K$5) -> 18451.396 | L34: =Inputs!L43*IF(Inputs!$E43="Real",1,L$5) -> 18087.83 | M34: =Inputs!M43*IF(Inputs!$E43="Real",1,M$5) -> 17731.429 | N34: =Inputs!N43*IF(Inputs!$E43="Real",1,N$5) -> 17382.049 | O34: =Inputs!O43*IF(Inputs!$E43="Real",1,O$5) -> 17039.554 | ... AZ34: =Inputs!AZ43*IF(Inputs!$E43="Real",1,AZ$5) -> 0
D35: Compliance Testing | E35: Real | F35: =Analysis_year -> 2025 | G35: =Inputs!G44 -> 0 | H35: =Inputs!H44*IF(Inputs!$E44="Real",1,H$5) -> 9793.2642 | I35: =Inputs!I44*IF(Inputs!$E44="Real",1,I$5) -> 9600.2982 | J35: =Inputs!J44*IF(Inputs!$E44="Real",1,J$5) -> 0 | K35: =Inputs!K44*IF(Inputs!$E44="Real",1,K$5) -> 0 | L35: =Inputs!L44*IF(Inputs!$E44="Real",1,L$5) -> 0 | M35: =Inputs!M44*IF(Inputs!$E44="Real",1,M$5) -> 0 | N35: =Inputs!N44*IF(Inputs!$E44="Real",1,N$5) -> 0 | O35: =Inputs!O44*IF(Inputs!$E44="Real",1,O$5) -> 0 | ... AZ35: =Inputs!AZ44*IF(Inputs!$E44="Real",1,AZ$5) -> 0
D36: Optimisation | E36: Real | F36: =Analysis_year -> 2025 | G36: =Inputs!G45 -> 0 | H36: =Inputs!H45*IF(Inputs!$E45="Real",1,H$5) -> 0 | I36: =Inputs!I45*IF(Inputs!$E45="Real",1,I$5) -> 0 | J36: =Inputs!J45*IF(Inputs!$E45="Real",1,J$5) -> 0 | K36: =Inputs!K45*IF(Inputs!$E45="Real",1,K$5) -> 0 | L36: =Inputs!L45*IF(Inputs!$E45="Real",1,L$5) -> 0 | M36: =Inputs!M45*IF(Inputs!$E45="Real",1,M$5) -> 0 | N36: =Inputs!N45*IF(Inputs!$E45="Real",1,N$5) -> 0 | O36: =Inputs!O45*IF(Inputs!$E45="Real",1,O$5) -> 0 | ... AZ36: =Inputs!AZ45*IF(Inputs!$E45="Real",1,AZ$5) -> 0
D37: Utilities and Consumables | E37: Real | F37: =Analysis_year -> 2025 | G37: =Inputs!G46 -> 0 | H37: =Inputs!H46*IF(Inputs!$E46="Real",1,H$5) -> 0 | I37: =Inputs!I46*IF(Inputs!$E46="Real",1,I$5) -> 0 | J37: =Inputs!J46*IF(Inputs!$E46="Real",1,J$5) -> 0 | K37: =Inputs!K46*IF(Inputs!$E46="Real",1,K$5) -> 0 | L37: =Inputs!L46*IF(Inputs!$E46="Real",1,L$5) -> 0 | M37: =Inputs!M46*IF(Inputs!$E46="Real",1,M$5) -> 0 | N37: =Inputs!N46*IF(Inputs!$E46="Real",1,N$5) -> 0 | O37: =Inputs!O46*IF(Inputs!$E46="Real",1,O$5) -> 0 | ... AZ37: =Inputs!AZ46*IF(Inputs!$E46="Real",1,AZ$5) -> 0
D38: Other | E38: Real | F38: =Analysis_year -> 2025 | G38: =Inputs!G47 -> 0 | H38: =Inputs!H47*IF(Inputs!$E47="Real",1,H$5) -> 0 | I38: =Inputs!I47*IF(Inputs!$E47="Real",1,I$5) -> 0 | J38: =Inputs!J47*IF(Inputs!$E47="Real",1,J$5) -> 0 | K38: =Inputs!K47*IF(Inputs!$E47="Real",1,K$5) -> 0 | L38: =Inputs!L47*IF(Inputs!$E47="Real",1,L$5) -> 0 | M38: =Inputs!M47*IF(Inputs!$E47="Real",1,M$5) -> 0 | N38: =Inputs!N47*IF(Inputs!$E47="Real",1,N$5) -> 0 | O38: =Inputs!O47*IF(Inputs!$E47="Real",1,O$5) -> 0 | ... AZ38: =Inputs!AZ47*IF(Inputs!$E47="Real",1,AZ$5) -> 0
D39: ="Total non-fuel opex in "&Analysis_year&" dollars" -> Total non-fuel opex in 2025 dollars | H39: =SUBTOTAL(109,Opex_NonFuel_PP[2026]) -> 127312.43 | I39: =SUBTOTAL(109,Opex_NonFuel_PP[2027]) -> 124803.88 | J39: =SUBTOTAL(109,Opex_NonFuel_PP[2028]) -> 112933.61 | K39: =SUBTOTAL(109,Opex_NonFuel_PP[2029]) -> 110708.37 | L39: =SUBTOTAL(109,Opex_NonFuel_PP[2030]) -> 108526.98 | M39: =SUBTOTAL(109,Opex_NonFuel_PP[2031]) -> 106388.57 | N39: =SUBTOTAL(109,Opex_NonFuel_PP[2032]) -> 104292.3 | O39: =SUBTOTAL(109,Opex_NonFuel_PP[2033]) -> 102237.33 | P39: =SUBTOTAL(109,Opex_NonFuel_PP[2034]) -> 100222.85 | Q39: =SUBTOTAL(109,Opex_NonFuel_PP[2035]) -> 98248.061 | R39: =SUBTOTAL(109,Opex_NonFuel_PP[2036]) -> 96312.186 | S39: =SUBTOTAL(109,Opex_NonFuel_PP[2037]) -> 94414.456 | T39: =SUBTOTAL(109,Opex_NonFuel_PP[2038]) -> 92554.118 | U39: =SUBTOTAL(109,Opex_NonFuel_PP[2039]) -> 90730.436 | V39: =SUBTOTAL(109,Opex_NonFuel_PP[2040]) -> 88942.688 | W39: =SUBTOTAL(109,Opex_NonFuel_PP[2041]) -> 87190.166 | X39: =SUBTOTAL(109,Opex_NonFuel_PP[2042]) -> 85472.175 | Y39: =SUBTOTAL(109,Opex_NonFuel_PP[2043]) -> 83788.036 | Z39: =SUBTOTAL(109,Opex_NonFuel_PP[2044]) -> 82137.08 | AA39: =SUBTOTAL(109,Opex_NonFuel_PP[2045]) -> 80518.655 | AB39: =SUBTOTAL(109,Opex_NonFuel_PP[2046]) -> 78932.12 | AC39: =SUBTOTAL(109,Opex_NonFuel_PP[2047]) -> 77376.845 | AD39: =SUBTOTAL(109,Opex_NonFuel_PP[2048]) -> 0 | AE39: =SUBTOTAL(109,Opex_NonFuel_PP[2049]) -> 0 | AF39: =SUBTOTAL(109,Opex_NonFuel_PP[2050]) -> 0 | AG39: =SUBTOTAL(109,Opex_NonFuel_PP[2051]) -> 0 | AH39: =SUBTOTAL(109,Opex_NonFuel_PP[2052]) -> 0 | AI39: =SUBTOTAL(109,Opex_NonFuel_PP[2053]) -> 0 | AJ39: =SUBTOTAL(109,Opex_NonFuel_PP[2054]) -> 0 | AK39: =SUBTOTAL(109,Opex_NonFuel_PP[2055]) -> 0 | AL39: =SUBTOTAL(109,Opex_NonFuel_PP[2056]) -> 0 | AM39: =SUBTOTAL(109,Opex_NonFuel_PP[2057]) -> 0 | AN39: =SUBTOTAL(109,Opex_NonFuel_PP[2058]) -> 0 | AO39: =SUBTOTAL(109,Opex_NonFuel_PP[2059]) -> 0 | AP39: =SUBTOTAL(109,Opex_NonFuel_PP[2060]) -> 0 | AQ39: =SUBTOTAL(109,Opex_NonFuel_PP[2061]) -> 0 | AR39: =SUBTOTAL(109,Opex_NonFuel_PP[2062]) -> 0 | AS39: =SUBTOTAL(109,Opex_NonFuel_PP[2063]) -> 0 | AT39: =SUBTOTAL(109,Opex_NonFuel_PP[2064]) -> 0 | AU39: =SUBTOTAL(109,Opex_NonFuel_PP[2065]) -> 0 | AV39: =SUBTOTAL(109,Opex_NonFuel_PP[2066]) -> 0 | AW39: =SUBTOTAL(109,Opex_NonFuel_PP[2067]) -> 0 | AX39: =SUBTOTAL(109,Opex_NonFuel_PP[2068]) -> 0 | AY39: =SUBTOTAL(109,Opex_NonFuel_PP[2069]) -> 0 | AZ39: =SUBTOTAL(109,Opex_NonFuel_PP[2070]) -> 0
A41: Base Case (BC) | D41: Opex item | E41: Value basis | F41: Base year | G41: Applicant comment | H41: 2026 | I41: 2027 | J41: 2028 | K41: 2029 | L41: 2030 | M41: 2031 | N41: 2032 | O41: 2033 | P41: 2034 | Q41: 2035 | R41: 2036 | S41: 2037 | T41: 2038 | U41: 2039 | V41: 2040 | W41: 2041 | X41: 2042 | Y41: 2043 | Z41: 2044 | AA41: 2045 | AB41: 2046 | AC41: 2047 | AD41: 2048 | AE41: 2049 | AF41: 2050 | AG41: 2051 | AH41: 2052 | AI41: 2053 | AJ41: 2054 | AK41: 2055 | AL41: 2056 | AM41: 2057 | AN41: 2058 | AO41: 2059 | AP41: 2060 | AQ41: 2061 | AR41: 2062 | AS41: 2063 | AT41: 2064 | AU41: 2065 | AV41: 2066 | AW41: 2067 | AX41: 2068 | AY41: 2069 | AZ41: 2070
D42: Energy costs (already handled separately) | E42: Real | F42: =Analysis_year -> 2025 | G42: =Inputs!G53 -> 0 | H42: =Inputs!H53*IF(Inputs!$E53="Real",1,H$5) -> 0 | I42: =Inputs!I53*IF(Inputs!$E53="Real",1,I$5) -> 0 | J42: =Inputs!J53*IF(Inputs!$E53="Real",1,J$5) -> 0 | K42: =Inputs!K53*IF(Inputs!$E53="Real",1,K$5) -> 0 | L42: =Inputs!L53*IF(Inputs!$E53="Real",1,L$5) -> 0 | M42: =Inputs!M53*IF(Inputs!$E53="Real",1,M$5) -> 0 | N42: =Inputs!N53*IF(Inputs!$E53="Real",1,N$5) -> 0 | O42: =Inputs!O53*IF(Inputs!$E53="Real",1,O$5) -> 0 | ... AZ42: =Inputs!AZ53*IF(Inputs!$E53="Real",1,AZ$5) -> 0
D43: Equipment Operation Costs | E43: Real | F43: =Analysis_year -> 2025 | G43: =Inputs!G54 -> 0 | H43: =Inputs!H54*IF(Inputs!$E54="Real",1,H$5) -> 88139.378 | I43: =Inputs!I54*IF(Inputs!$E54="Real",1,I$5) -> 86402.684 | J43: =Inputs!J54*IF(Inputs!$E54="Real",1,J$5) -> 84700.21 | K43: =Inputs!K54*IF(Inputs!$E54="Real",1,K$5) -> 83031.281 | L43: =Inputs!L54*IF(Inputs!$E54="Real",1,L$5) -> 81395.237 | M43: =Inputs!M54*IF(Inputs!$E54="Real",1,M$5) -> 79791.429 | N43: =Inputs!N54*IF(Inputs!$E54="Real",1,N$5) -> 78219.222 | O43: =Inputs!O54*IF(Inputs!$E54="Real",1,O$5) -> 76677.995 | ... AZ43: =Inputs!AZ54*IF(Inputs!$E54="Real",1,AZ$5) -> 0
D44: Maintenance, Repairs, Inspections | E44: Real | F44: =Analysis_year -> 2025 | G44: =Inputs!G55 -> 0 | H44: =Inputs!H55*IF(Inputs!$E55="Real",1,H$5) -> 97932.642 | I44: =Inputs!I55*IF(Inputs!$E55="Real",1,I$5) -> 96002.982 | J44: =Inputs!J55*IF(Inputs!$E55="Real",1,J$5) -> 94111.344 | K44: =Inputs!K55*IF(Inputs!$E55="Real",1,K$5) -> 92256.979 | L44: =Inputs!L55*IF(Inputs!$E55="Real",1,L$5) -> 90439.152 | M44: =Inputs!M55*IF(Inputs!$E55="Real",1,M$5) -> 88657.143 | N44: =Inputs!N55*IF(Inputs!$E55="Real",1,N$5) -> 86910.247 | O44: =Inputs!O55*IF(Inputs!$E55="Real",1,O$5) -> 85197.772 | ... AZ44: =Inputs!AZ55*IF(Inputs!$E55="Real",1,AZ$5) -> 0
D45: Compliance Testing | E45: Real | F45: =Analysis_year -> 2025 | G45: =Inputs!G56 -> 0 | H45: =Inputs!H56*IF(Inputs!$E56="Real",1,H$5) -> 0 | I45: =Inputs!I56*IF(Inputs!$E56="Real",1,I$5) -> 0 | J45: =Inputs!J56*IF(Inputs!$E56="Real",1,J$5) -> 0 | K45: =Inputs!K56*IF(Inputs!$E56="Real",1,K$5) -> 0 | L45: =Inputs!L56*IF(Inputs!$E56="Real",1,L$5) -> 0 | M45: =Inputs!M56*IF(Inputs!$E56="Real",1,M$5) -> 0 | N45: =Inputs!N56*IF(Inputs!$E56="Real",1,N$5) -> 0 | O45: =Inputs!O56*IF(Inputs!$E56="Real",1,O$5) -> 0 | ... AZ45: =Inputs!AZ56*IF(Inputs!$E56="Real",1,AZ$5) -> 0
D46: Optimisation | E46: Real | F46: =Analysis_year -> 2025 | G46: =Inputs!G57 -> 0 | H46: =Inputs!H57*IF(Inputs!$E57="Real",1,H$5) -> 0 | I46: =Inputs!I57*IF(Inputs!$E57="Real",1,I$5) -> 0 | J46: =Inputs!J57*IF(Inputs!$E57="Real",1,J$5) -> 0 | K46: =Inputs!K57*IF(Inputs!$E57="Real",1,K$5) -> 0 | L46: =Inputs!L57*IF(Inputs!$E57="Real",1,L$5) -> 0 | M46: =Inputs!M57*IF(Inputs!$E57="Real",1,M$5) -> 0 | N46: =Inputs!N57*IF(Inputs!$E57="Real",1,N$5) -> 0 | O46: =Inputs!O57*IF(Inputs!$E57="Real",1,O$5) -> 0 | ... AZ46: =Inputs!AZ57*IF(Inputs!$E57="Real",1,AZ$5) -> 0
D47: Utilities and Consumables | E47: Real | F47: =Analysis_year -> 2025 | G47: =Inputs!G58 -> 0 | H47: =Inputs!H58*IF(Inputs!$E58="Real",1,H$5) -> 0 | I47: =Inputs!I58*IF(Inputs!$E58="Real",1,I$5) -> 0 | J47: =Inputs!J58*IF(Inputs!$E58="Real",1,J$5) -> 0 | K47: =Inputs!K58*IF(Inputs!$E58="Real",1,K$5) -> 0 | L47: =Inputs!L58*IF(Inputs!$E58="Real",1,L$5) -> 0 | M47: =Inputs!M58*IF(Inputs!$E58="Real",1,M$5) -> 0 | N47: =Inputs!N58*IF(Inputs!$E58="Real",1,N$5) -> 0 | O47: =Inputs!O58*IF(Inputs!$E58="Real",1,O$5) -> 0 | ... AZ47: =Inputs!AZ58*IF(Inputs!$E58="Real",1,AZ$5) -> 0
...

Sheet Calculations
B1: Final Year
A2: Proposed Project | B2: =IF('Project description'!B13="Retrofit of existing asset",'Project description'!B14,YEAR('Project description'!B11)+'Project description'!B15) -> 2047
A3: Base Case | B3: =IF('Project description'!B13="Retrofit of existing asset",'Project description'!B14,YEAR('Project description'!B11)+'Project description'!B17) -> 2047
A5: Emissions
B6: Fuel type | C6: 2026 | D6: 2027 | E6: 2028 | F6: 2029 | G6: 2030 | H6: 2031 | I6: 2032 | J6: 2033 | K6: 2034 | L6: 2035 | M6: 2036 | N6: 2037 | O6: 2038 | P6: 2039 | Q6: 2040 | R6: 2041 | S6: 2042 | T6: 2043 | U6: 2044 | V6: 2045 | W6: 2046 | X6: 2047 | Y6: 2048 | Z6: 2049 | AA6: 2050 | AB6: 2051 | AC6: 2052 | AD6: 2053 | AE6: 2054 | AF6: 2055 | AG6: 2056 | AH6: 2057 | AI6: 2058 | AJ6: 2059 | AK6: 2060 | AL6: 2061 | AM6: 2062 | AN6: 2063 | AO6: 2064 | AP6: 2065 | AQ6: 2066 | AR6: 2067 | AS6: 2068 | AT6: 2069 | AU6: 2070
A7: PP | B7: Electricity | C7: =Inputs!H65*Data!M2 -> 8.0918911 | D7: =Inputs!I65*Data!N2 -> 338.32076 | E7: =Inputs!J65*Data!O2 -> 326.68902 | F7: =Inputs!K65*Data!P2 -> 306.20368 | G7: =Inputs!L65*Data!Q2 -> 274.51783 | H7: =Inputs!M65*Data!R2 -> 269.14981 | I7: =Inputs!N65*Data!S2 -> 275.11837 | J7: =Inputs!O65*Data!T2 -> 275.17089 | ... AU7: =Inputs!AZ65*Data!BE2 -> 0
B8: Natural Gas | C8: =Inputs!H66*Data!M3 -> 4004.84 | D8: =Inputs!I66*Data!N3 -> 0 | E8: =Inputs!J66*Data!O3 -> 0 | F8: =Inputs!K66*Data!P3 -> 0 | G8: =Inputs!L66*Data!Q3 -> 0 | H8: =Inputs!M66*Data!R3 -> 0 | I8: =Inputs!N66*Data!S3 -> 0 | J8: =Inputs!O66*Data!T3 -> 0 | ... AU8: =Inputs!AZ66*Data!BE3 -> 0
B9: Coal - sub bituminous | C9: =Inputs!H67*Data!M4 -> 0 | D9: =Inputs!I67*Data!N4 -> 0 | E9: =Inputs!J67*Data!O4 -> 0 | F9: =Inputs!K67*Data!P4 -> 0 | G9: =Inputs!L67*Data!Q4 -> 0 | H9: =Inputs!M67*Data!R4 -> 0 | I9: =Inputs!N67*Data!S4 -> 0 | J9: =Inputs!O67*Data!T4 -> 0 | ... AU9: =Inputs!AZ67*Data!BE4 -> 0
B10: Coal - bituminous | C10: =Inputs!H68*Data!M5 -> 0 | D10: =Inputs!I68*Data!N5 -> 0 | E10: =Inputs!J68*Data!O5 -> 0 | F10: =Inputs!K68*Data!P5 -> 0 | G10: =Inputs!L68*Data!Q5 -> 0 | H10: =Inputs!M68*Data!R5 -> 0 | I10: =Inputs!N68*Data!S5 -> 0 | J10: =Inputs!O68*Data!T5 -> 0 | ... AU10: =Inputs!AZ68*Data!BE5 -> 0
B11: Coal - lignite | C11: =Inputs!H69*Data!M6 -> 0 | D11: =Inputs!I69*Data!N6 -> 0 | E11: =Inputs!J69*Data!O6 -> 0 | F11: =Inputs!K69*Data!P6 -> 0 | G11: =Inputs!L69*Data!Q6 -> 0 | H11: =Inputs!M69*Data!R6 -> 0 | I11: =Inputs!N69*Data!S6 -> 0 | J11: =Inputs!O69*Data!T6 -> 0 | ... AU11: =Inputs!AZ69*Data!BE6 -> 0
B12: Diesel | C12: =Inputs!H70*Data!M7 -> 0 | D12: =Inputs!I70*Data!N7 -> 0 | E12: =Inputs!J70*Data!O7 -> 0 | F12: =Inputs!K70*Data!P7 -> 0 | G12: =Inputs!L70*Data!Q7 -> 0 | H12: =Inputs!M70*Data!R7 -> 0 | I12: =Inputs!N70*Data!S7 -> 0 | J12: =Inputs!O70*Data!T7 -> 0 | ... AU12: =Inputs!AZ70*Data!BE7 -> 0
B13: LPG | C13: =Inputs!H71*Data!M8 -> 0 | D13: =Inputs!I71*Data!N8 -> 0 | E13: =Inputs!J71*Data!O8 -> 0 | F13: =Inputs!K71*Data!P8 -> 0 | G13: =Inputs!L71*Data!Q8 -> 0 | H13: =Inputs!M71*Data!R8 -> 0 | I13: =Inputs!N71*Data!S8 -> 0 | J13: =Inputs!O71*Data!T8 -> 0 | ... AU13: =Inputs!AZ71*Data!BE8 -> 0
B14: Light fuel oil | C14: =Inputs!H72*Data!M9 -> 0 | D14: =Inputs!I72*Data!N9 -> 0 | E14: =Inputs!J72*Data!O9 -> 0 | F14: =Inputs!K72*Data!P9 -> 0 | G14: =Inputs!L72*Data!Q9 -> 0 | H14: =Inputs!M72*Data!R9 -> 0 | I14: =Inputs!N72*Data!S9 -> 0 | J14: =Inputs!O72*Data!T9 -> 0 | ... AU14: =Inputs!AZ72*Data!BE9 -> 0
B15: Heavy fuel oil | C15: =Inputs!H73*Data!M10 -> 0 | D15: =Inputs!I73*Data!N10 -> 0 | E15: =Inputs!J73*Data!O10 -> 0 | F15: =Inputs!K73*Data!P10 -> 0 | G15: =Inputs!L73*Data!Q10 -> 0 | H15: =Inputs!M73*Data!R10 -> 0 | I15: =Inputs!N73*Data!S10 -> 0 | J15: =Inputs!O73*Data!T10 -> 0 | ... AU15: =Inputs!AZ73*Data!BE10 -> 0
B16: Geothermal | C16: =Inputs!H74*Data!M11 -> 0 | D16: =Inputs!I74*Data!N11 -> 0 | E16: =Inputs!J74*Data!O11 -> 0 | F16: =Inputs!K74*Data!P11 -> 0 | G16: =Inputs!L74*Data!Q11 -> 0 | H16: =Inputs!M74*Data!R11 -> 0 | I16: =Inputs!N74*Data!S11 -> 0 | J16: =Inputs!O74*Data!T11 -> 0 | ... AU16: =Inputs!AZ74*Data!BE11 -> 0
B17: Wood or wood chips | C17: =Inputs!H75*Data!M12 -> 0 | D17: =Inputs!I75*Data!N12 -> 0 | E17: =Inputs!J75*Data!O12 -> 0 | F17: =Inputs!K75*Data!P12 -> 0 | G17: =Inputs!L75*Data!Q12 -> 0 | H17: =Inputs!M75*Data!R12 -> 0 | I17: =Inputs!N75*Data!S12 -> 0 | J17: =Inputs!O75*Data!T12 -> 0 | ... AU17: =Inputs!AZ75*Data!BE12 -> 0
A18: BC | B18: Electricity | C18: =Inputs!H78*Data!M2 -> 8.0918911 | D18: =Inputs!I78*Data!N2 -> 8.1052825 | E18: =Inputs!J78*Data!O2 -> 7.8266164 | F18: =Inputs!K78*Data!P2 -> 7.3358411 | G18: =Inputs!L78*Data!Q2 -> 6.5767307 | H18: =Inputs!M78*Data!R2 -> 6.448127 | I18: =Inputs!N78*Data!S2 -> 6.5911182 | J18: =Inputs!O78*Data!T2 -> 6.5923763 | ... AU18: =Inputs!AZ78*Data!BE2 -> 0
B19: Natural Gas | C19: =Inputs!H79*Data!M3 -> 4004.84 | D19: =Inputs!I79*Data!N3 -> 4004.84 | E19: =Inputs!J79*Data!O3 -> 4004.84 | F19: =Inputs!K79*Data!P3 -> 4004.84 | G19: =Inputs!L79*Data!Q3 -> 4004.84 | H19: =Inputs!M79*Data!R3 -> 4004.84 | I19: =Inputs!N79*Data!S3 -> 4004.84 | J19: =Inputs!O79*Data!T3 -> 4004.84 | ... AU19: =Inputs!AZ79*Data!BE3 -> 0
B20: Coal - sub bituminous | C20: =Inputs!H80*Data!M4 -> 0 | D20: =Inputs!I80*Data!N4 -> 0 | E20: =Inputs!J80*Data!O4 -> 0 | F20: =Inputs!K80*Data!P4 -> 0 | G20: =Inputs!L80*Data!Q4 -> 0 | H20: =Inputs!M80*Data!R4 -> 0 | I20: =Inputs!N80*Data!S4 -> 0 | J20: =Inputs!O80*Data!T4 -> 0 | ... AU20: =Inputs!AZ80*Data!BE4 -> 0
B21: Coal - bituminous | C21: =Inputs!H81*Data!M5 -> 0 | D21: =Inputs!I81*Data!N5 -> 0 | E21: =Inputs!J81*Data!O5 -> 0 | F21: =Inputs!K81*Data!P5 -> 0 | G21: =Inputs!L81*Data!Q5 -> 0 | H21: =Inputs!M81*Data!R5 -> 0 | I21: =Inputs!N81*Data!S5 -> 0 | J21: =Inputs!O81*Data!T5 -> 0 | ... AU21: =Inputs!AZ81*Data!BE5 -> 0
B22: Coal - lignite | C22: =Inputs!H82*Data!M6 -> 0 | D22: =Inputs!I82*Data!N6 -> 0 | E22: =Inputs!J82*Data!O6 -> 0 | F22: =Inputs!K82*Data!P6 -> 0 | G22: =Inputs!L82*Data!Q6 -> 0 | H22: =Inputs!M82*Data!R6 -> 0 | I22: =Inputs!N82*Data!S6 -> 0 | J22: =Inputs!O82*Data!T6 -> 0 | ... AU22: =Inputs!AZ82*Data!BE6 -> 0
B23: Diesel | C23: =Inputs!H83*Data!M7 -> 0 | D23: =Inputs!I83*Data!N7 -> 0 | E23: =Inputs!J83*Data!O7 -> 0 | F23: =Inputs!K83*Data!P7 -> 0 | G23: =Inputs!L83*Data!Q7 -> 0 | H23: =Inputs!M83*Data!R7 -> 0 | I23: =Inputs!N83*Data!S7 -> 0 | J23: =Inputs!O83*Data!T7 -> 0 | ... AU23: =Inputs!AZ83*Data!BE7 -> 0
B24: LPG | C24: =Inputs!H84*Data!M8 -> 0 | D24: =Inputs!I84*Data!N8 -> 0 | E24: =Inputs!J84*Data!O8 -> 0 | F24: =Inputs!K84*Data!P8 -> 0 | G24: =Inputs!L84*Data!Q8 -> 0 | H24: =Inputs!M84*Data!R8 -> 0 | I24: =Inputs!N84*Data!S8 -> 0 | J24: =Inputs!O84*Data!T8 -> 0 | ... AU24: =Inputs!AZ84*Data!BE8 -> 0
B25: Light fuel oil | C25: =Inputs!H85*Data!M9 -> 0 | D25: =Inputs!I85*Data!N9 -> 0 | E25: =Inputs!J85*Data!O9 -> 0 | F25: =Inputs!K85*Data!P9 -> 0 | G25: =Inputs!L85*Data!Q9 -> 0 | H25: =Inputs!M85*Data!R9 -> 0 | I25: =Inputs!N85*Data!S9 -> 0 | J25: =Inputs!O85*Data!T9 -> 0 | ... AU25: =Inputs!AZ85*Data!BE9 -> 0
B26: Heavy fuel oil | C26: =Inputs!H86*Data!M10 -> 0 | D26: =Inputs!I86*Data!N10 -> 0 | E26: =Inputs!J86*Data!O10 -> 0 | F26: =Inputs!K86*Data!P10 -> 0 | G26: =Inputs!L86*Data!Q10 -> 0 | H26: =Inputs!M86*Data!R10 -> 0 | I26: =Inputs!N86*Data!S10 -> 0 | J26: =Inputs!O86*Data!T10 -> 0 | ... AU26: =Inputs!AZ86*Data!BE10 -> 0
B27: Geothermal | C27: =Inputs!H87*Data!M11 -> 0 | D27: =Inputs!I87*Data!N11 -> 0 | E27: =Inputs!J87*Data!O11 -> 0 | F27: =Inputs!K87*Data!P11 -> 0 | G27: =Inputs!L87*Data!Q11 -> 0 | H27: =Inputs!M87*Data!R11 -> 0 | I27: =Inputs!N87*Data!S11 -> 0 | J27: =Inputs!O87*Data!T11 -> 0 | ... AU27: =Inputs!AZ87*Data!BE11 -> 0
B28: Wood or wood chips | C28: =Inputs!H88*Data!M12 -> 0 | D28: =Inputs!I88*Data!N12 -> 0 | E28: =Inputs!J88*Data!O12 -> 0 | F28: =Inputs!K88*Data!P12 -> 0 | G28: =Inputs!L88*Data!Q12 -> 0 | H28: =Inputs!M88*Data!R12 -> 0 | I28: =Inputs!N88*Data!S12 -> 0 | J28: =Inputs!O88*Data!T12 -> 0 | ... AU28: =Inputs!AZ88*Data!BE12 -> 0
A29: Total PP | C29: =SUM(C7:C17) -> 4012.9319 | D29: =SUM(D7:D17) -> 338.32076 | E29: =SUM(E7:E17) -> 326.68902 | F29: =SUM(F7:F17) -> 306.20368 | G29: =SUM(G7:G17) -> 274.51783 | H29: =SUM(H7:H17) -> 269.14981 | I29: =SUM(I7:I17) -> 275.11837 | J29: =SUM(J7:J17) -> 275.17089 | ... AU29: =SUM(AU7:AU17) -> 0
A30: Total BC | C30: =SUM(C18:C28) -> 4012.9319 | D30: =SUM(D18:D28) -> 4012.9453 | E30: =SUM(E18:E28) -> 4012.6666 | F30: =SUM(F18:F28) -> 4012.1758 | G30: =SUM(G18:G28) -> 4011.4167 | H30: =SUM(H18:H28) -> 4011.2881 | I30: =SUM(I18:I28) -> 4011.4311 | J30: =SUM(J18:J28) -> 4011.4324 | ... AU30: =SUM(AU18:AU28) -> 0
A32: Fuel costs without ETS costs
B33: Fuel type
A34: PP | B34: =B7 -> Electricity | C34: =IF(Inputs!$E92="Real",Inputs!H119,Inputs!H119/Inputs!H$10)-C7*INDEX(Data!$L$26:$BE$26,MATCH(C$6,Data!$L$17:$BE$17,0)) -> 28575.827 | D34: =IF(Inputs!$E92="Real",Inputs!I119,Inputs!I119/Inputs!I$10)-D7*INDEX(Data!$L$26:$BE$26,MATCH(D$6,Data!$L$17:$BE$17,0)) -> 1187603.9 | E34: =IF(Inputs!$E92="Real",Inputs!J119,Inputs!J119/Inputs!J$10)-E7*INDEX(Data!$L$26:$BE$26,MATCH(E$6,Data!$L$17:$BE$17,0)) -> 1184925.3 | F34: =IF(Inputs!$E92="Real",Inputs!K119,Inputs!K119/Inputs!K$10)-F7*INDEX(Data!$L$26:$BE$26,MATCH(F$6,Data!$L$17:$BE$17,0)) -> 1184246 | G34: =IF(Inputs!$E92="Real",Inputs!L119,Inputs!L119/Inputs!L$10)-G7*INDEX(Data!$L$26:$BE$26,MATCH(G$6,Data!$L$17:$BE$17,0)) -> 1187162.5 | H34: =IF(Inputs!$E92="Real",Inputs!M119,Inputs!M119/Inputs!M$10)-H7*INDEX(Data!$L$26:$BE$26,MATCH(H$6,Data!$L$17:$BE$17,0)) -> 1186550.6 | I34: =IF(Inputs!$E92="Real",Inputs!N119,Inputs!N119/Inputs!N$10)-I7*INDEX(Data!$L$26:$BE$26,MATCH(I$6,Data!$L$17:$BE$17,0)) -> 1183168.5 | J34: =IF(Inputs!$E92="Real",Inputs!O119,Inputs!O119/Inputs!O$10)-J7*INDEX(Data!$L$26:$BE$26,MATCH(J$6,Data!$L$17:$BE$17,0)) -> 1180953.9 | ... AU34: =IF(Inputs!$E92="Real",Inputs!AZ119,Inputs!AZ119/Inputs!AZ$10)-AU7*INDEX(Data!$L$26:$BE$26,MATCH(AU$6,Data!$L$17:$BE$17,0)) -> 0
B35: =B14 -> Light fuel oil | C35: =IF(Inputs!$E93="Real",Inputs!H127,Inputs!H127/Inputs!H$10)-C14*INDEX(Data!$L$26:$BE$26,MATCH(C$6,Data!$L$17:$BE$17,0)) -> 0 | D35: =IF(Inputs!$E93="Real",Inputs!I127,Inputs!I127/Inputs!I$10)-D14*INDEX(Data!$L$26:$BE$26,MATCH(D$6,Data!$L$17:$BE$17,0)) -> 0 | E35: =IF(Inputs!$E93="Real",Inputs!J127,Inputs!J127/Inputs!J$10)-E14*INDEX(Data!$L$26:$BE$26,MATCH(E$6,Data!$L$17:$BE$17,0)) -> 0 | F35: =IF(Inputs!$E93="Real",Inputs!K127,Inputs!K127/Inputs!K$10)-F14*INDEX(Data!$L$26:$BE$26,MATCH(F$6,Data!$L$17:$BE$17,0)) -> 0 | G35: =IF(Inputs!$E93="Real",Inputs!L127,Inputs!L127/Inputs!L$10)-G14*INDEX(Data!$L$26:$BE$26,MATCH(G$6,Data!$L$17:$BE$17,0)) -> 0 | H35: =IF(Inputs!$E93="Real",Inputs!M127,Inputs!M127/Inputs!M$10)-H14*INDEX(Data!$L$26:$BE$26,MATCH(H$6,Data!$L$17:$BE$17,0)) -> 0 | I35: =IF(Inputs!$E93="Real",Inputs!N127,Inputs!N127/Inputs!N$10)-I14*INDEX(Data!$L$26:$BE$26,MATCH(I$6,Data!$L$17:$BE$17,0)) -> 0 | J35: =IF(Inputs!$E93="Real",Inputs!O127,Inputs!O127/Inputs!O$10)-J14*INDEX(Data!$L$26:$BE$26,MATCH(J$6,Data!$L$17:$BE$17,0)) -> 0 | ... AU35: =IF(Inputs!$E93="Real",Inputs!AZ127,Inputs!AZ127/Inputs!AZ$10)-AU14*INDEX(Data!$L$26:$BE$26,MATCH(AU$6,Data!$L$17:$BE$17,0)) -> 0
B36: =B15 -> Heavy fuel oil | C36: =IF(Inputs!$E94="Real",Inputs!H128,Inputs!H128/Inputs!H$10)-C15*INDEX(Data!$L$26:$BE$26,MATCH(C$6,Data!$L$17:$BE$17,0)) -> 0 | D36: =IF(Inputs!$E94="Real",Inputs!I128,Inputs!I128/Inputs!I$10)-D15*INDEX(Data!$L$26:$BE$26,MATCH(D$6,Data!$L$17:$BE$17,0)) -> 0 | E36: =IF(Inputs!$E94="Real",Inputs!J128,Inputs!J128/Inputs!J$10)-E15*INDEX(Data!$L$26:$BE$26,MATCH(E$6,Data!$L$17:$BE$17,0)) -> 0 | F36: =IF(Inputs!$E94="Real",Inputs!K128,Inputs!K128/Inputs!K$10)-F15*INDEX(Data!$L$26:$BE$26,MATCH(F$6,Data!$L$17:$BE$17,0)) -> 0 | G36: =IF(Inputs!$E94="Real",Inputs!L128,Inputs!L128/Inputs!L$10)-G15*INDEX(Data!$L$26:$BE$26,MATCH(G$6,Data!$L$17:$BE$17,0)) -> 0 | H36: =IF(Inputs!$E94="Real",Inputs!M128,Inputs!M128/Inputs!M$10)-H15*INDEX(Data!$L$26:$BE$26,MATCH(H$6,Data!$L$17:$BE$17,0)) -> 0 | I36: =IF(Inputs!$E94="Real",Inputs!N128,Inputs!N128/Inputs!N$10)-I15*INDEX(Data!$L$26:$BE$26,MATCH(I$6,Data!$L$17:$BE$17,0)) -> 0 | J36: =IF(Inputs!$E94="Real",Inputs!O128,Inputs!O128/Inputs!O$10)-J15*INDEX(Data!$L$26:$BE$26,MATCH(J$6,Data!$L$17:$BE$17,0)) -> 0 | ... AU36: =IF(Inputs!$E94="Real",Inputs!AZ128,Inputs!AZ128/Inputs!AZ$10)-AU15*INDEX(Data!$L$26:$BE$26,MATCH(AU$6,Data!$L$17:$BE$17,0)) -> 0
B37: =B16 -> Geothermal | C37: =IF(Inputs!$E102="Real",Inputs!H129,Inputs!H129/Inputs!H$10)-C16*INDEX(Data!$L$26:$BE$26,MATCH(C$6,Data!$L$17:$BE$17,0)) -> 0 | D37: =IF(Inputs!$E102="Real",Inputs!I129,Inputs!I129/Inputs!I$10)-D16*INDEX(Data!$L$26:$BE$26,MATCH(D$6,Data!$L$17:$BE$17,0)) -> 0 | E37: =IF(Inputs!$E102="Real",Inputs!J129,Inputs!J129/Inputs!J$10)-E16*INDEX(Data!$L$26:$BE$26,MATCH(E$6,Data!$L$17:$BE$17,0)) -> 0 | F37: =IF(Inputs!$E102="Real",Inputs!K129,Inputs!K129/Inputs!K$10)-F16*INDEX(Data!$L$26:$BE$26,MATCH(F$6,Data!$L$17:$BE$17,0)) -> 0 | G37: =IF(Inputs!$E102="Real",Inputs!L129,Inputs!L129/Inputs!L$10)-G16*INDEX(Data!$L$26:$BE$26,MATCH(G$6,Data!$L$17:$BE$17,0)) -> 0 | H37: =IF(Inputs!$E102="Real",Inputs!M129,Inputs!M129/Inputs!M$10)-H16*INDEX(Data!$L$26:$BE$26,MATCH(H$6,Data!$L$17:$BE$17,0)) -> 0 | I37: =IF(Inputs!$E102="Real",Inputs!N129,Inputs!N129/Inputs!N$10)-I16*INDEX(Data!$L$26:$BE$26,MATCH(I$6,Data!$L$17:$BE$17,0)) -> 0 | J37: =IF(Inputs!$E102="Real",Inputs!O129,Inputs!O129/Inputs!O$10)-J16*INDEX(Data!$L$26:$BE$26,MATCH(J$6,Data!$L$17:$BE$17,0)) -> 0 | ... AU37: =IF(Inputs!$E102="Real",Inputs!AZ129,Inputs!AZ129/Inputs!AZ$10)-AU16*INDEX(Data!$L$26:$BE$26,MATCH(AU$6,Data!$L$17:$BE$17,0)) -> 0
B38: =B17 -> Wood or wood chips | C38: =IF(Inputs!$E103="Real",Inputs!H130,Inputs!H130/Inputs!H$10)-C17*INDEX(Data!$L$26:$BE$26,MATCH(C$6,Data!$L$17:$BE$17,0)) -> 745410.3 | D38: =IF(Inputs!$E103="Real",Inputs!I130,Inputs!I130/Inputs!I$10)-D17*INDEX(Data!$L$26:$BE$26,MATCH(D$6,Data!$L$17:$BE$17,0)) -> 1304358.7 | E38: =IF(Inputs!$E103="Real",Inputs!J130,Inputs!J130/Inputs!J$10)-E17*INDEX(Data!$L$26:$BE$26,MATCH(E$6,Data!$L$17:$BE$17,0)) -> 1330576.3 | F38: =IF(Inputs!$E103="Real",Inputs!K130,Inputs!K130/Inputs!K$10)-F17*INDEX(Data!$L$26:$BE$26,MATCH(F$6,Data!$L$17:$BE$17,0)) -> 1357320.8 | G38: =IF(Inputs!$E103="Real",Inputs!L130,Inputs!L130/Inputs!L$10)-G17*INDEX(Data!$L$26:$BE$26,MATCH(G$6,Data!$L$17:$BE$17,0)) -> 1384603 | H38: =IF(Inputs!$E103="Real",Inputs!M130,Inputs!M130/Inputs!M$10)-H17*INDEX(Data!$L$26:$BE$26,MATCH(H$6,Data!$L$17:$BE$17,0)) -> 1412433.5 | I38: =IF(Inputs!$E103="Real",Inputs!N130,Inputs!N130/Inputs!N$10)-I17*INDEX(Data!$L$26:$BE$26,MATCH(I$6,Data!$L$17:$BE$17,0)) -> 1440823.4 | J38: =IF(Inputs!$E103="Real",Inputs!O130,Inputs!O130/Inputs!O$10)-J17*INDEX(Data!$L$26:$BE$26,MATCH(J$6,Data!$L$17:$BE$17,0)) -> 1469784 | ... AU38: =IF(Inputs!$E103="Real",Inputs!AZ130,Inputs!AZ130/Inputs!AZ$10)-AU17*INDEX(Data!$L$26:$BE$26,MATCH(AU$6,Data!$L$17:$BE$17,0)) -> 0
A39: BC | B39: =B18 -> Electricity | C39: =IF(Inputs!$E105="Real",Inputs!H134,Inputs!H134/Inputs!H$10)-C18*INDEX(Data!$L$26:$BE$26,MATCH(C$6,Data!$L$17:$BE$17,0)) -> 28575.827 | D39: =IF(Inputs!$E105="Real",Inputs!I134,Inputs!I134/Inputs!I$10)-D18*INDEX(Data!$L$26:$BE$26,MATCH(D$6,Data!$L$17:$BE$17,0)) -> 28451.891 | E39: =IF(Inputs!$E105="Real",Inputs!J134,Inputs!J134/Inputs!J$10)-E18*INDEX(Data!$L$26:$BE$26,MATCH(E$6,Data!$L$17:$BE$17,0)) -> 28387.717 | F39: =IF(Inputs!$E105="Real",Inputs!K134,Inputs!K134/Inputs!K$10)-F18*INDEX(Data!$L$26:$BE$26,MATCH(F$6,Data!$L$17:$BE$17,0)) -> 28371.443 | G39: =IF(Inputs!$E105="Real",Inputs!L134,Inputs!L134/Inputs!L$10)-G18*INDEX(Data!$L$26:$BE$26,MATCH(G$6,Data!$L$17:$BE$17,0)) -> 28441.315 | H39: =IF(Inputs!$E105="Real",Inputs!M134,Inputs!M134/Inputs!M$10)-H18*INDEX(Data!$L$26:$BE$26,MATCH(H$6,Data!$L$17:$BE$17,0)) -> 28426.657 | I39: =IF(Inputs!$E105="Real",Inputs!N134,Inputs!N134/Inputs!N$10)-I18*INDEX(Data!$L$26:$BE$26,MATCH(I$6,Data!$L$17:$BE$17,0)) -> 28345.629 | J39: =IF(Inputs!$E105="Real",Inputs!O134,Inputs!O134/Inputs!O$10)-J18*INDEX(Data!$L$26:$BE$26,MATCH(J$6,Data!$L$17:$BE$17,0)) -> 28292.575 | ... AU39: =IF(Inputs!$E105="Real",Inputs!AZ134,Inputs!AZ134/Inputs!AZ$10)-AU18*INDEX(Data!$L$26:$BE$26,MATCH(AU$6,Data!$L$17:$BE$17,0)) -> 0
B40: =B25 -> Light fuel oil | C40: =IF(Inputs!$E113="Real",Inputs!H142,Inputs!H142/Inputs!H$10)-C25*INDEX(Data!$L$26:$BE$26,MATCH(C$6,Data!$L$17:$BE$17,0)) -> 0 | D40: =IF(Inputs!$E113="Real",Inputs!I142,Inputs!I142/Inputs!I$10)-D25*INDEX(Data!$L$26:$BE$26,MATCH(D$6,Data!$L$17:$BE$17,0)) -> 0 | E40: =IF(Inputs!$E113="Real",Inputs!J142,Inputs!J142/Inputs!J$10)-E25*INDEX(Data!$L$26:$BE$26,MATCH(E$6,Data!$L$17:$BE$17,0)) -> 0 | F40: =IF(Inputs!$E113="Real",Inputs!K142,Inputs!K142/Inputs!K$10)-F25*INDEX(Data!$L$26:$BE$26,MATCH(F$6,Data!$L$17:$BE$17,0)) -> 0 | G40: =IF(Inputs!$E113="Real",Inputs!L142,Inputs!L142/Inputs!L$10)-G25*INDEX(Data!$L$26:$BE$26,MATCH(G$6,Data!$L$17:$BE$17,0)) -> 0 | H40: =IF(Inputs!$E113="Real",Inputs!M142,Inputs!M142/Inputs!M$10)-H25*INDEX(Data!$L$26:$BE$26,MATCH(H$6,Data!$L$17:$BE$17,0)) -> 0 | I40: =IF(Inputs!$E113="Real",Inputs!N142,Inputs!N142/Inputs!N$10)-I25*INDEX(Data!$L$26:$BE$26,MATCH(I$6,Data!$L$17:$BE$17,0)) -> 0 | J40: =IF(Inputs!$E113="Real",Inputs!O142,Inputs!O142/Inputs!O$10)-J25*INDEX(Data!$L$26:$BE$26,MATCH(J$6,Data!$L$17:$BE$17,0)) -> 0 | ... AU40: =IF(Inputs!$E113="Real",Inputs!AZ142,Inputs!AZ142/Inputs!AZ$10)-AU25*INDEX(Data!$L$26:$BE$26,MATCH(AU$6,Data!$L$17:$BE$17,0)) -> 0
B41: =B26 -> Heavy fuel oil | C41: =IF(Inputs!$E114="Real",Inputs!H143,Inputs!H143/Inputs!H$10)-C26*INDEX(Data!$L$26:$BE$26,MATCH(C$6,Data!$L$17:$BE$17,0)) -> 0 | D41: =IF(Inputs!$E114="Real",Inputs!I143,Inputs!I143/Inputs!I$10)-D26*INDEX(Data!$L$26:$BE$26,MATCH(D$6,Data!$L$17:$BE$17,0)) -> 0 | E41: =IF(Inputs!$E114="Real",Inputs!J143,Inputs!J143/Inputs!J$10)-E26*INDEX(Data!$L$26:$BE$26,MATCH(E$6,Data!$L$17:$BE$17,0)) -> 0 | F41: =IF(Inputs!$E114="Real",Inputs!K143,Inputs!K143/Inputs!K$10)-F26*INDEX(Data!$L$26:$BE$26,MATCH(F$6,Data!$L$17:$BE$17,0)) -> 0 | G41: =IF(Inputs!$E114="Real",Inputs!L143,Inputs!L143/Inputs!L$10)-G26*INDEX(Data!$L$26:$BE$26,MATCH(G$6,Data!$L$17:$BE$17,0)) -> 0 | H41: =IF(Inputs!$E114="Real",Inputs!M143,Inputs!M143/Inputs!M$10)-H26*INDEX(Data!$L$26:$BE$26,MATCH(H$6,Data!$L$17:$BE$17,0)) -> 0 | I41: =IF(Inputs!$E114="Real",Inputs!N143,Inputs!N143/Inputs!N$10)-I26*INDEX(Data!$L$26:$BE$26,MATCH(I$6,Data!$L$17:$BE$17,0)) -> 0 | J41: =IF(Inputs!$E114="Real",Inputs!O143,Inputs!O143/Inputs!O$10)-J26*INDEX(Data!$L$26:$BE$26,MATCH(J$6,Data!$L$17:$BE$17,0)) -> 0 | ... AU41: =IF(Inputs!$E114="Real",Inputs!AZ143,Inputs!AZ143/Inputs!AZ$10)-AU26*INDEX(Data!$L$26:$BE$26,MATCH(AU$6,Data!$L$17:$BE$17,0)) -> 0
B42: =B27 -> Geothermal | C42: =IF(Inputs!$E115="Real",Inputs!H144,Inputs!H144/Inputs!H$10)-C27*INDEX(Data!$L$26:$BE$26,MATCH(C$6,Data!$L$17:$BE$17,0)) -> 0 | D42: =IF(Inputs!$E115="Real",Inputs!I144,Inputs!I144/Inputs!I$10)-D27*INDEX(Data!$L$26:$BE$26,MATCH(D$6,Data!$L$17:$BE$17,0)) -> 0 | E42: =IF(Inputs!$E115="Real",Inputs!J144,Inputs!J144/Inputs!J$10)-E27*INDEX(Data!$L$26:$BE$26,MATCH(E$6,Data!$L$17:$BE$17,0)) -> 0 | F42: =IF(Inputs!$E115="Real",Inputs!K144,Inputs!K144/Inputs!K$10)-F27*INDEX(Data!$L$26:$BE$26,MATCH(F$6,Data!$L$17:$BE$17,0)) -> 0 | G42: =IF(Inputs!$E115="Real",Inputs!L144,Inputs!L144/Inputs!L$10)-G27*INDEX(Data!$L$26:$BE$26,MATCH(G$6,Data!$L$17:$BE$17,0)) -> 0 | H42: =IF(Inputs!$E115="Real",Inputs!M144,Inputs!M144/Inputs!M$10)-H27*INDEX(Data!$L$26:$BE$26,MATCH(H$6,Data!$L$17:$BE$17,0)) -> 0 | I42: =IF(Inputs!$E115="Real",Inputs!N144,Inputs!N144/Inputs!N$10)-I27*INDEX(Data!$L$26:$BE$26,MATCH(I$6,Data!$L$17:$BE$17,0)) -> 0 | J42: =IF(Inputs!$E115="Real",Inputs!O144,Inputs!O144/Inputs!O$10)-J27*INDEX(Data!$L$26:$BE$26,MATCH(J$6,Data!$L$17:$BE$17,0)) -> 0 | ... AU42: =IF(Inputs!$E115="Real",Inputs!AZ144,Inputs!AZ144/Inputs!AZ$10)-AU27*INDEX(Data!$L$26:$BE$26,MATCH(AU$6,Data!$L$17:$BE$17,0)) -> 0
...

Sheet Results
A1: National perspective
A2: NPV | B2: 2% | C2: 8%
A3: PP | B3: =Calculations!C75 -> -467103.28 | C3: =Calculations!D75 -> -999211.31
A4: BC | B4: =Calculations!C76 -> -15905412 | C4: =Calculations!D76 -> -8270002.4
A5: Preferred: | B5: =IF(B3>B4,$A3,$A4) -> PP | C5: =IF(C3>C4,$A3,$A4) -> PP
A8: Private perspective
A9: Private Returns | B9: Pre-tax Nominal | C9: Column1
B10: =ReturnType -> Return on Equity | C10: IRR
A11: PP | B11: =Calculations!B86 -> -623430.52 | C11: =Calculations!C86 -> 0.098125932
A12: BC | B12: =Calculations!B87 -> 24222.319 | C12: =Calculations!C87 -> 0.18369181
A13: Preferred: | B13: =IF(B11>B12,$A11,$A12) -> BC | C13: =IF(C11>C12,$A11,$A12) -> BC

Sheet Data
A1: Sectors | B1: Regions | D1: Fuel | E1: Consump-tion unit | F1: GJ conversion | G1: Unit for Emission Factor | H1: Emission factor (kg CO2-e/unit) | I1: Emission factor (t CO2-e/ consumption unit) | K1: Emission factors by year | L1: 2025 | M1: 2026 | N1: 2027 | O1: 2028 | P1: 2029 | Q1: 2030 | R1: 2031 | S1: 2032 | T1: 2033 | U1: 2034 | V1: 2035 | W1: 2036 | X1: 2037 | Y1: 2038 | Z1: 2039 | AA1: 2040 | AB1: 2041 | AC1: 2042 | AD1: 2043 | AE1: 2044 | AF1: 2045 | AG1: 2046 | AH1: 2047 | AI1: 2048 | AJ1: 2049 | AK1: 2050 | AL1: 2051 | AM1: 2052 | AN1: 2053 | AO1: 2054 | AP1: 2055 | AQ1: 2056 | AR1: 2057 | AS1: 2058 | AT1: 2059 | AU1: 2060 | AV1: 2061 | AW1: 2062 | AX1: 2063 | AY1: 2064 | AZ1: 2065 | BA1: 2066 | BB1: 2067 | BC1: 2068 | BD1: 2069 | BE1: 2070
