Workbook
Name Analysis_year: 'Project description'!$B$13
Name FinalYear_BC: Calculations!$B$3
Name FinalYear_PP: Calculations!$B$2
Name HurdleRateBasis: 'Project description'!$B$29
Name Occasion: Lists!$A$21:$A$32
Name ReturnType: 'Project description'!$B$30
Name Start_Yr: 'Project description'!$B$11

Sheet Guidance
B1: Concessionary Loans Application Template
B3: This spreadsheet is for the applicant to fill in information about the 'Proposed Project' (i.e., the project for which Concessions Loan funds are sought) and also a 'Base Case' (i.e., the outcomes if the project were not to proceed). For example, the Proposed Project could be the replacement of a coal-fired boiler with a biomass boiler, whereas the Base Case could be the coal-fired boiler continuing to operate.
B6: The spreadsheet consists of the following tabs:
B7: Project description: | E7: This has some input cells for applicants to fill in regarding the name and type of project, starting dates and the applicant's investment criteria.
B8: Inputs: | E8: This is the main tab for the applicant to fill in projected Capex and Opex cashflows for the Proposed Project and the Base Case, as well as projected fuel consumption for both situations.
B9: Scratch: | E9: This is a tab which applicants can use if they wish to do their own bespoke calculations - noting that the rest of the spreadsheet is 'locked-down' to enable EECA to extract and evaluate data in a rigorous fashion.
B11: Real values: | E11: This tab includes calculated values derived from both the Project description and Inputs tabs.
B12: Results: | E12: This tab shows a summary of energy savings (GJ and $), as well as repayments. NOTE: a row to enter payments made to date is include in repayments.

Sheet Project description
A1: Input data
A2: Project information | B2: Information should be included on the proposed project (assuming the loan is given) and the base case (what you would do without the loan)
A3: Field | B3: Value | C3: Notes
A4: Occasion | B4: <Select>
A5: ProjectID | C5: For EECA use only
A6: Applicant's name
A7: Sector | B7: <Select>
A8: Region | B8: <Select>
A9: Name for proposed project
A10: Date of application submission (dd/mm/yy)
A11: First year of expenditure (yyyy)
A12: Expected commissioning date of proposed project (dd/mm/yy)
A13: Analysis year - this should be the current year
A15: Project type | B15: <Select> | C15: =IF(B15="Retrofit of existing asset","Project assumed to last only as long as the life of the existing asset","")
A16: =INDEX(Lists!$C$2:$C$5,MATCH(Lists!B6,Lists!$B$2:$B$5,0))
A17: =IF(INDEX(Lists!G2:G5,MATCH(Lists!B6,Lists!$B$2:$B$6,0))=0,"",INDEX(Lists!G2:G5,MATCH(Lists!B6,Lists!$B$2:$B$6,0))) | C17: =IF(FinalYear_PP = 1900, "", "Final year = "&FinalYear_PP)
A18: =IF(INDEX(Lists!E2:E5,MATCH(Lists!B6,Lists!$B$2:$B$5,0))=0,"",INDEX(Lists!E2:E5,MATCH(Lists!B6,Lists!$B$2:$B$5,0))) | B18: <Select>
A19: =IF(INDEX(Lists!F2:F5,MATCH(Lists!B6,Lists!$B$2:$B$5,0))=0,"",INDEX(Lists!F2:F5,MATCH(Lists!B6,Lists!$B$2:$B$5,0))) | C19: =IF(FinalYear_BC=1900, "", "Final year = "&FinalYear_BC)
A21: Does the project replace the use of coal for industrial process heat? | B21: <Select>
A22: If this project replaces coal consumption for industrial process heat, does the project bring forward the time of replacement from the start of 2037? | B22: <Select> | C22: =IF(AND(B22="Yes",B21="Yes"),"The base case used for analysis should be that of just meeting the regulated coal phase-out date of 2037","")
A23: Is this a heat pump project? | B23: <Select>
A25: What level of loan contribution are you requesting? ($)
A26: Start date? (dd/mm/yyyy)
A27: How long would the loan be for? (years) | C27: =IF(Start_Yr+B27=0, "", "Full repayment by "&Start_Yr+B27)
A28: What is your hurdle rate for this investment (%)
A29: What basis is used for the hurdle rate? | B29: <Select>
A30: Is the hurdle rate for the return on equity only or for the whole investment | B30: <Select>

Sheet Inputs
A2: Inflation
A3: Cashflow values may be specified in real (ie, current year values) or nominal (values for the year of the cost or revenue item)
A4: ="All values for the current year ("&'Project description'!B13&") should be in current dollar values" -> All values for the current year () should be in current dollar values
A5: I will include my own inflation assumptions | B5: Yes
A6: If an inflation rate has been used to produce a future nominal value, please note it below | H6: 2025 | I6: =H6+1 -> 2026 | J6: =I6+1 -> 2027 | K6: =J6+1 -> 2028 | L6: =K6+1 -> 2029 | M6: =L6+1 -> 2030 | N6: =M6+1 -> 2031 | O6: =N6+1 -> 2032 | P6: =O6+1 -> 2033 | ... BA6: =AZ6+1 -> 2070
A7: Inflation rate in the year | B7: Please enter the inflation rate you have assumed here: | H7: 0.03 | I7: 0.02 | J7: 0.02 | K7: 0.02 | L7: 0.02 | M7: 0.02 | N7: 0.02 | O7: 0.02 | P7: 0.02 | Q7: 0.02 | R7: 0.02 | S7: 0.02 | T7: 0.02 | U7: 0.02 | V7: 0.02 | W7: 0.02 | X7: 0.02 | Y7: 0.02 | Z7: 0.02 | AA7: 0.02 | AB7: 0.02 | AC7: 0.02 | AD7: 0.02 | AE7: 0.02 | AF7: 0.02 | AG7: 0.02 | AH7: =AG7 -> 0.02 | AI7: =AH7 -> 0.02 | AJ7: =AI7 -> 0.02 | AK7: =AJ7 -> 0.02 | AL7: =AK7 -> 0.02 | AM7: =AL7 -> 0.02 | AN7: =AM7 -> 0.02 | AO7: =AN7 -> 0.02 | ... BA7: =AZ7 -> 0.02
A8: =IF(B5="Yes","Inflation rate","Default inflation rate") -> Inflation rate | H8: =IF($B$5="Yes",H7,Data!L33) -> 0.03 | I8: =IF($B$5="Yes",I7,Data!M33) -> 0.02 | J8: =IF($B$5="Yes",J7,Data!N33) -> 0.02 | K8: =IF($B$5="Yes",K7,Data!O33) -> 0.02 | L8: =IF($B$5="Yes",L7,Data!P33) -> 0.02 | M8: =IF($B$5="Yes",M7,Data!Q33) -> 0.02 | N8: =IF($B$5="Yes",N7,Data!R33) -> 0.02 | O8: =IF($B$5="Yes",O7,Data!S33) -> 0.02 | ... BA8: =IF($B$5="Yes",BA7,Data!BE33) -> 0.02
A9: Proportion of year | H9: =IF(YEAR('Project description'!B10)=H6,(DATE(H6,12,31)-'Project description'!B12)/365,1) -> 1 | I9: =IF(YEAR('Project description'!C10)=I6,(DATE(I6,12,31)-'Project description'!C12)/365,1) -> 1 | J9: =IF(YEAR('Project description'!D10)=J6,(DATE(J6,12,31)-'Project description'!D12)/365,1) -> 1 | K9: =IF(YEAR('Project description'!E10)=K6,(DATE(K6,12,31)-'Project description'!E12)/365,1) -> 1 | L9: =IF(YEAR('Project description'!F10)=L6,(DATE(L6,12,31)-'Project description'!F12)/365,1) -> 1 | M9: =IF(YEAR('Project description'!G10)=M6,(DATE(M6,12,31)-'Project description'!G12)/365,1) -> 1 | N9: =IF(YEAR('Project description'!H10)=N6,(DATE(N6,12,31)-'Project description'!H12)/365,1) -> 1 | O9: =IF(YEAR('Project description'!I10)=O6,(DATE(O6,12,31)-'Project description'!I12)/365,1) -> 1 | ... BA9: =IF(YEAR('Project description'!AU10)=BA6,(DATE(BA6,12,31)-'Project description'!AU12)/365,1) -> 1
A10: Inflator to end of year - use this to convert real values to nominal | H10: =IF(H6=Analysis_year,1+(H8*H9),IF(H6<Analysis_year,1/((1/I10)*(1+I8*I9)),G10*(1+G8*G9))) -> 0 | I10: =IF(I6=Analysis_year,1+(I8*I9),IF(I6<Analysis_year,1/((1/J10)*(1+J8*J9)),H10*(1+H8*H9))) -> 0 | J10: =IF(J6=Analysis_year,1+(J8*J9),IF(J6<Analysis_year,1/((1/K10)*(1+K8*K9)),I10*(1+I8*I9))) -> 0 | K10: =IF(K6=Analysis_year,1+(K8*K9),IF(K6<Analysis_year,1/((1/L10)*(1+L8*L9)),J10*(1+J8*J9))) -> 0 | L10: =IF(L6=Analysis_year,1+(L8*L9),IF(L6<Analysis_year,1/((1/M10)*(1+M8*M9)),K10*(1+K8*K9))) -> 0 | M10: =IF(M6=Analysis_year,1+(M8*M9),IF(M6<Analysis_year,1/((1/N10)*(1+N8*N9)),L10*(1+L8*L9))) -> 0 | N10: =IF(N6=Analysis_year,1+(N8*N9),IF(N6<Analysis_year,1/((1/O10)*(1+O8*O9)),M10*(1+M8*M9))) -> 0 | O10: =IF(O6=Analysis_year,1+(O8*O9),IF(O6<Analysis_year,1/((1/P10)*(1+P8*P9)),N10*(1+N8*N9))) -> 0 | ... BA10: =IF(BA6=Analysis_year,1+(BA8*BA9),IF(BA6<Analysis_year,1/((1/BB10)*(1+BB8*BB9)),AZ10*(1+AZ8*AZ9))) -> 0
A11: Deflator - use this to convert nominal values to real | H11: =IFERROR(1/H10,0) -> 0 | I11: =IFERROR(1/I10,0) -> 0 | J11: =IFERROR(1/J10,0) -> 0 | K11: =IFERROR(1/K10,0) -> 0 | L11: =IFERROR(1/L10,0) -> 0 | M11: =IFERROR(1/M10,0) -> 0 | N11: =IFERROR(1/N10,0) -> 0 | O11: =IFERROR(1/O10,0) -> 0 | ... BA11: =IFERROR(1/BA10,0) -> 0
A13: 1) Capital expenditure (CAPEX) ($) - please enter all costs as positive numbers
D14: Value basis | E14: Nominal
A15: Proposed Project (PP) | D15: Capex item | E15: Value basis | G15: Applicant comment | H15: 2025 | I15: 2026 | J15: 2027 | K15: 2028 | L15: 2029 | M15: 2030 | N15: 2031 | O15: 2032 | P15: 2033 | Q15: 2034 | R15: 2035 | S15: 2036 | T15: 2037 | U15: 2038 | V15: 2039 | W15: 2040 | X15: 2041 | Y15: 2042 | Z15: 2043 | AA15: 2044 | AB15: 2045 | AC15: 2046 | AD15: 2047 | AE15: 2048 | AF15: 2049 | AG15: 2050 | AH15: 2051 | AI15: 2052 | AJ15: 2053 | AK15: 2054 | AL15: 2055 | AM15: 2056 | AN15: 2057 | AO15: 2058 | AP15: 2059 | AQ15: 2060 | AR15: 2061 | AS15: 2062 | AT15: 2063 | AU15: 2064 | AV15: 2065 | AW15: 2066 | AX15: 2067 | AY15: 2068 | AZ15: 2069 | BA15: 2070
A16: ="Please provide data through to "&FinalYear_PP -> Please provide data through to 1900 | D16: Equipment purchase | E16: =E$14 -> Nominal | F16: =IF(E16="Nominal","",Analysis_year&" values")
D17: Civil works | E17: =E$14 -> Nominal | F17: =IF(E17="Nominal","",Analysis_year&" values")
D18: Electrical works | E18: =E$14 -> Nominal | F18: =IF(E18="Nominal","",Analysis_year&" values")
D19: Installation | E19: =E$14 -> Nominal | F19: =IF(E19="Nominal","",Analysis_year&" values")
D20: Indirect costs | E20: =E$14 -> Nominal | F20: =IF(E20="Nominal","",Analysis_year&" values")
D21: Project management | E21: =E$14 -> Nominal | F21: =IF(E21="Nominal","",Analysis_year&" values")
D22: Other | E22: =E$14 -> Nominal | F22: =IF(E22="Nominal","",Analysis_year&" values")
D23: ="Total capex in "&Analysis_year&" dollars" -> Total capex in dollars | H23: =SUM(H16:H22)*IF($E$14="Real",1,H$11) -> 0 | I23: =SUM(I16:I22)*IF($E$14="Real",1,I$11) -> 0 | J23: =SUM(J16:J22)*IF($E$14="Real",1,J$11) -> 0 | K23: =SUM(K16:K22)*IF($E$14="Real",1,K$11) -> 0 | L23: =SUM(L16:L22)*IF($E$14="Real",1,L$11) -> 0 | M23: =SUM(M16:M22)*IF($E$14="Real",1,M$11) -> 0 | N23: =SUM(N16:N22)*IF($E$14="Real",1,N$11) -> 0 | O23: =SUM(O16:O22)*IF($E$14="Real",1,O$11) -> 0 | ... BA23: =SUM(BA16:BA22)*IF($E$14="Real",1,BA$11) -> 0
D24: Total capex in nominal dollars | H24: =SUM(H16:H22)*IF($E$14="Real",H10,1) -> 0 | I24: =SUM(I16:I22)*IF($E$14="Real",I10,1) -> 0 | J24: =SUM(J16:J22)*IF($E$14="Real",J10,1) -> 0 | K24: =SUM(K16:K22)*IF($E$14="Real",K10,1) -> 0 | L24: =SUM(L16:L22)*IF($E$14="Real",L10,1) -> 0 | M24: =SUM(M16:M22)*IF($E$14="Real",M10,1) -> 0 | N24: =SUM(N16:N22)*IF($E$14="Real",N10,1) -> 0 | O24: =SUM(O16:O22)*IF($E$14="Real",O10,1) -> 0 | ... BA24: =SUM(BA16:BA22)*IF($E$14="Real",BA10,1) -> 0
D26: Value basis | E26: Real
A27: Base Case (BC) | D27: Capex item | E27: Value basis | G27: Applicant comment | H27: 2025 | I27: 2026 | J27: 2027 | K27: 2028 | L27: 2029 | M27: 2030 | N27: 2031 | O27: 2032 | P27: 2033 | Q27: 2034 | R27: 2035 | S27: 2036 | T27: 2037 | U27: 2038 | V27: 2039 | W27: 2040 | X27: 2041 | Y27: 2042 | Z27: 2043 | AA27: 2044 | AB27: 2045 | AC27: 2046 | AD27: 2047 | AE27: 2048 | AF27: 2049 | AG27: 2050 | AH27: 2051 | AI27: 2052 | AJ27: 2053 | AK27: 2054 | AL27: 2055 | AM27: 2056 | AN27: 2057 | AO27: 2058 | AP27: 2059 | AQ27: 2060 | AR27: 2061 | AS27: 2062 | AT27: 2063 | AU27: 2064 | AV27: 2065 | AW27: 2066 | AX27: 2067 | AY27: 2068 | AZ27: 2069 | BA27: 2070
A28: ="Please provide data through to "&FinalYear_BC -> Please provide data through to 1900 | D28: Equipment purchase | E28: =$E$26 -> Real | F28: =IF(E28="Nominal","",Analysis_year&" values") -> values
D29: Civil works | E29: =$E$26 -> Real | F29: =IF(E29="Nominal","",Analysis_year&" values") -> values
D30: Electrical works | E30: =$E$26 -> Real | F30: =IF(E30="Nominal","",Analysis_year&" values") -> values
D31: Installation | E31: =$E$26 -> Real | F31: =IF(E31="Nominal","",Analysis_year&" values") -> values
D32: Indirect costs | E32: =$E$26 -> Real | F32: =IF(E32="Nominal","",Analysis_year&" values") -> values
D33: Project management | E33: =$E$26 -> Real | F33: =IF(E33="Nominal","",Analysis_year&" values") -> values
D34: Other | E34: =$E$26 -> Real | F34: =IF(E34="Nominal","",Analysis_year&" values") -> values
D35: ="Total capex in "&Analysis_year&" dollars" -> Total capex in dollars | H35: =SUM(H28:H34)*IF($E$26="Real",1,H$11) -> 0 | I35: =SUM(I28:I34)*IF($E$26="Real",1,I$11) -> 0 | J35: =SUM(J28:J34)*IF($E$26="Real",1,J$11) -> 0 | K35: =SUM(K28:K34)*IF($E$26="Real",1,K$11) -> 0 | L35: =SUM(L28:L34)*IF($E$26="Real",1,L$11) -> 0 | M35: =SUM(M28:M34)*IF($E$26="Real",1,M$11) -> 0 | N35: =SUM(N28:N34)*IF($E$26="Real",1,N$11) -> 0 | O35: =SUM(O28:O34)*IF($E$26="Real",1,O$11) -> 0 | ... BA35: =SUM(BA28:BA34)*IF($E$26="Real",1,BA$11) -> 0
D36: Total capex in nominal dollars | H36: =SUM(H28:H34)*IF($E$26="Real",H$10,1) -> 0 | I36: =SUM(I28:I34)*IF($E$26="Real",I$10,1) -> 0 | J36: =SUM(J28:J34)*IF($E$26="Real",J$10,1) -> 0 | K36: =SUM(K28:K34)*IF($E$26="Real",K$10,1) -> 0 | L36: =SUM(L28:L34)*IF($E$26="Real",L$10,1) -> 0 | M36: =SUM(M28:M34)*IF($E$26="Real",M$10,1) -> 0 | N36: =SUM(N28:N34)*IF($E$26="Real",N$10,1) -> 0 | O36: =SUM(O28:O34)*IF($E$26="Real",O$10,1) -> 0 | ... BA36: =SUM(BA28:BA34)*IF($E$26="Real",BA$10,1) -> 0
A39: 2) Operating & Maintenance Expenditure (OPEX) ($) - please enter all costs as positive numbers
A40: 2a) Non-fuel opex | D40: Value basis | E40: Nominal
A41: Proposed Project (PP) | D41: Opex item | E41: Value basis | G41: Applicant comment | H41: 2025 | I41: 2026 | J41: 2027 | K41: 2028 | L41: 2029 | M41: 2030 | N41: 2031 | O41: 2032 | P41: 2033 | Q41: 2034 | R41: 2035 | S41: 2036 | T41: 2037 | U41: 2038 | V41: 2039 | W41: 2040 | X41: 2041 | Y41: 2042 | Z41: 2043 | AA41: 2044 | AB41: 2045 | AC41: 2046 | AD41: 2047 | AE41: 2048 | AF41: 2049 | AG41: 2050 | AH41: 2051 | AI41: 2052 | AJ41: 2053 | AK41: 2054 | AL41: 2055 | AM41: 2056 | AN41: 2057 | AO41: 2058 | AP41: 2059 | AQ41: 2060 | AR41: 2061 | AS41: 2062 | AT41: 2063 | AU41: 2064 | AV41: 2065 | AW41: 2066 | AX41: 2067 | AY41: 2068 | AZ41: 2069 | BA41: 2070
A42: ="Please provide data through to "&FinalYear_PP -> Please provide data through to 1900 | D42: Equipment Operation Costs | E42: =$E$40 -> Nominal | F42: =IF(E42="Nominal","",Analysis_year&" values")
D43: Maintenance, Repairs, Inspections | E43: =$E$40 -> Nominal | F43: =IF(E43="Nominal","",Analysis_year&" values")
D44: Compliance Testing | E44: =$E$40 -> Nominal | F44: =IF(E44="Nominal","",Analysis_year&" values")
D45: Optimisation | E45: =$E$40 -> Nominal | F45: =IF(E45="Nominal","",Analysis_year&" values")
...

Sheet Scratch

Sheet Real values
A2: Financial projection basis
L3: =Inputs!H6 -> 2025 | M3: =Inputs!I6 -> 2026 | N3: =Inputs!J6 -> 2027 | O3: =Inputs!K6 -> 2028 | P3: =Inputs!L6 -> 2029 | Q3: =Inputs!M6 -> 2030 | R3: =Inputs!N6 -> 2031 | S3: =Inputs!O6 -> 2032 | ... BE3: =Inputs!BA6 -> 2070
A4: Inflator - use this to convert real values to nominal | L4: =Inputs!H10 -> 0 | M4: =Inputs!I10 -> 0 | N4: =Inputs!J10 -> 0 | O4: =Inputs!K10 -> 0 | P4: =Inputs!L10 -> 0 | Q4: =Inputs!M10 -> 0 | R4: =Inputs!N10 -> 0 | S4: =Inputs!O10 -> 0 | ... BE4: =Inputs!BA10 -> 0
A5: Deflator - use this to convert nominal values to real | L5: =Inputs!H11 -> 0 | M5: =Inputs!I11 -> 0 | N5: =Inputs!J11 -> 0 | O5: =Inputs!K11 -> 0 | P5: =Inputs!L11 -> 0 | Q5: =Inputs!M11 -> 0 | R5: =Inputs!N11 -> 0 | S5: =Inputs!O11 -> 0 | ... BE5: =Inputs!BA11 -> 0
A7: 1) Capital expenditure (CAPEX) ($) - please enter all costs as positive numbers
A9: Proposed Project (PP) | D9: ProjectId | E9: LifeCycleMonths | F9: Scenario | G9: ExpenseType | H9: Capex item | I9: Value basis | J9: Base year | K9: Applicant comment | L9: 2025 | M9: 2026 | N9: 2027 | O9: 2028 | P9: 2029 | Q9: 2030 | R9: 2031 | S9: 2032 | T9: 2033 | U9: 2034 | V9: 2035 | W9: 2036 | X9: 2037 | Y9: 2038 | Z9: 2039 | AA9: 2040 | AB9: 2041 | AC9: 2042 | AD9: 2043 | AE9: 2044 | AF9: 2045 | AG9: 2046 | AH9: 2047 | AI9: 2048 | AJ9: 2049 | AK9: 2050 | AL9: 2051 | AM9: 2052 | AN9: 2053 | AO9: 2054 | AP9: 2055 | AQ9: 2056 | AR9: 2057 | AS9: 2058 | AT9: 2059 | AU9: 2060 | AV9: 2061 | AW9: 2062 | AX9: 2063 | AY9: 2064 | AZ9: 2065 | BA9: 2066 | BB9: 2067 | BC9: 2068 | BD9: 2069 | BE9: 2070
D10: ='Project description'!$B$5 -> 0 | E10: =Lists!$B$34 | F10: PP | G10: capex | H10: Equipment purchase | I10: Real | J10: =Analysis_year -> 0 | K10: =IF(Inputs!G16="","",Inputs!G16) | L10: =Inputs!H16*IF(Inputs!$E16="Real",1,L$5) -> 0 | M10: =Inputs!I16*IF(Inputs!$E16="Real",1,M$5) -> 0 | N10: =Inputs!J16*IF(Inputs!$E16="Real",1,N$5) -> 0 | O10: =Inputs!K16*IF(Inputs!$E16="Real",1,O$5) -> 0 | P10: =Inputs!L16*IF(Inputs!$E16="Real",1,P$5) -> 0 | Q10: =Inputs!M16*IF(Inputs!$E16="Real",1,Q$5) -> 0 | R10: =Inputs!N16*IF(Inputs!$E16="Real",1,R$5) -> 0 | S10: =Inputs!O16*IF(Inputs!$E16="Real",1,S$5) -> 0 | ... BE10: =Inputs!BA16*IF(Inputs!$E16="Real",1,BE$5) -> 0
D11: ='Project description'!$B$5 -> 0 | E11: =Lists!$B$34 | F11: PP | G11: capex | H11: Civil works | I11: Real | J11: =Analysis_year -> 0 | K11: =IF(Inputs!G17="","",Inputs!G17) | L11: =Inputs!H17*IF(Inputs!$E17="Real",1,L$5) -> 0 | M11: =Inputs!I17*IF(Inputs!$E17="Real",1,M$5) -> 0 | N11: =Inputs!J17*IF(Inputs!$E17="Real",1,N$5) -> 0 | O11: =Inputs!K17*IF(Inputs!$E17="Real",1,O$5) -> 0 | P11: =Inputs!L17*IF(Inputs!$E17="Real",1,P$5) -> 0 | Q11: =Inputs!M17*IF(Inputs!$E17="Real",1,Q$5) -> 0 | R11: =Inputs!N17*IF(Inputs!$E17="Real",1,R$5) -> 0 | S11: =Inputs!O17*IF(Inputs!$E17="Real",1,S$5) -> 0 | ... BE11: =Inputs!BA17*IF(Inputs!$E17="Real",1,BE$5) -> 0
D12: ='Project description'!$B$5 -> 0 | E12: =Lists!$B$34 | F12: PP | G12: capex | H12: Electrical works | I12: Real | J12: =Analysis_year -> 0 | K12: =IF(Inputs!G18="","",Inputs!G18) | L12: =Inputs!H18*IF(Inputs!$E18="Real",1,L$5) -> 0 | M12: =Inputs!I18*IF(Inputs!$E18="Real",1,M$5) -> 0 | N12: =Inputs!J18*IF(Inputs!$E18="Real",1,N$5) -> 0 | O12: =Inputs!K18*IF(Inputs!$E18="Real",1,O$5) -> 0 | P12: =Inputs!L18*IF(Inputs!$E18="Real",1,P$5) -> 0 | Q12: =Inputs!M18*IF(Inputs!$E18="Real",1,Q$5) -> 0 | R12: =Inputs!N18*IF(Inputs!$E18="Real",1,R$5) -> 0 | S12: =Inputs!O18*IF(Inputs!$E18="Real",1,S$5) -> 0 | ... BE12: =Inputs!BA18*IF(Inputs!$E18="Real",1,BE$5) -> 0
D13: ='Project description'!$B$5 -> 0 | E13: =Lists!$B$34 | F13: PP | G13: capex | H13: Installation | I13: Real | J13: =Analysis_year -> 0 | K13: =IF(Inputs!G19="","",Inputs!G19) | L13: =Inputs!H19*IF(Inputs!$E19="Real",1,L$5) -> 0 | M13: =Inputs!I19*IF(Inputs!$E19="Real",1,M$5) -> 0 | N13: =Inputs!J19*IF(Inputs!$E19="Real",1,N$5) -> 0 | O13: =Inputs!K19*IF(Inputs!$E19="Real",1,O$5) -> 0 | P13: =Inputs!L19*IF(Inputs!$E19="Real",1,P$5) -> 0 | Q13: =Inputs!M19*IF(Inputs!$E19="Real",1,Q$5) -> 0 | R13: =Inputs!N19*IF(Inputs!$E19="Real",1,R$5) -> 0 | S13: =Inputs!O19*IF(Inputs!$E19="Real",1,S$5) -> 0 | ... BE13: =Inputs!BA19*IF(Inputs!$E19="Real",1,BE$5) -> 0
D14: ='Project description'!$B$5 -> 0 | E14: =Lists!$B$34 | F14: PP | G14: capex | H14: Indirect costs | I14: Real | J14: =Analysis_year -> 0 | K14: =IF(Inputs!G20="","",Inputs!G20) | L14: =Inputs!H20*IF(Inputs!$E20="Real",1,L$5) -> 0 | M14: =Inputs!I20*IF(Inputs!$E20="Real",1,M$5) -> 0 | N14: =Inputs!J20*IF(Inputs!$E20="Real",1,N$5) -> 0 | O14: =Inputs!K20*IF(Inputs!$E20="Real",1,O$5) -> 0 | P14: =Inputs!L20*IF(Inputs!$E20="Real",1,P$5) -> 0 | Q14: =Inputs!M20*IF(Inputs!$E20="Real",1,Q$5) -> 0 | R14: =Inputs!N20*IF(Inputs!$E20="Real",1,R$5) -> 0 | S14: =Inputs!O20*IF(Inputs!$E20="Real",1,S$5) -> 0 | ... BE14: =Inputs!BA20*IF(Inputs!$E20="Real",1,BE$5) -> 0
D15: ='Project description'!$B$5 -> 0 | E15: =Lists!$B$34 | F15: PP | G15: capex | H15: Project management | I15: Real | J15: =Analysis_year -> 0 | K15: =IF(Inputs!G21="","",Inputs!G21) | L15: =Inputs!H21*IF(Inputs!$E21="Real",1,L$5) -> 0 | M15: =Inputs!I21*IF(Inputs!$E21="Real",1,M$5) -> 0 | N15: =Inputs!J21*IF(Inputs!$E21="Real",1,N$5) -> 0 | O15: =Inputs!K21*IF(Inputs!$E21="Real",1,O$5) -> 0 | P15: =Inputs!L21*IF(Inputs!$E21="Real",1,P$5) -> 0 | Q15: =Inputs!M21*IF(Inputs!$E21="Real",1,Q$5) -> 0 | R15: =Inputs!N21*IF(Inputs!$E21="Real",1,R$5) -> 0 | S15: =Inputs!O21*IF(Inputs!$E21="Real",1,S$5) -> 0 | ... BE15: =Inputs!BA21*IF(Inputs!$E21="Real",1,BE$5) -> 0
D16: ='Project description'!$B$5 -> 0 | E16: =Lists!$B$34 | F16: PP | G16: capex | H16: Other | I16: Real | J16: =Analysis_year -> 0 | K16: =IF(Inputs!G22="","",Inputs!G22) | L16: =Inputs!H22*IF(Inputs!$E22="Real",1,L$5) -> 0 | M16: =Inputs!I22*IF(Inputs!$E22="Real",1,M$5) -> 0 | N16: =Inputs!J22*IF(Inputs!$E22="Real",1,N$5) -> 0 | O16: =Inputs!K22*IF(Inputs!$E22="Real",1,O$5) -> 0 | P16: =Inputs!L22*IF(Inputs!$E22="Real",1,P$5) -> 0 | Q16: =Inputs!M22*IF(Inputs!$E22="Real",1,Q$5) -> 0 | R16: =Inputs!N22*IF(Inputs!$E22="Real",1,R$5) -> 0 | S16: =Inputs!O22*IF(Inputs!$E22="Real",1,S$5) -> 0 | ... BE16: =Inputs!BA22*IF(Inputs!$E22="Real",1,BE$5) -> 0
H17: ="Total capex in "&Analysis_year&" dollars" -> Total capex in dollars | L17: =SUBTOTAL(109,'Real values'!$L$10:$L$16) -> 0 | M17: =SUM(M10:M16)*IF($I$8="Real",1,N$5) -> 0 | N17: =SUM(N10:N16)*IF($I$8="Real",1,O$5) -> 0 | O17: =SUM(O10:O16)*IF($I$8="Real",1,P$5) -> 0 | P17: =SUM(P10:P16)*IF($I$8="Real",1,Q$5) -> 0 | Q17: =SUM(Q10:Q16)*IF($I$8="Real",1,R$5) -> 0 | R17: =SUM(R10:R16)*IF($I$8="Real",1,S$5) -> 0 | S17: =SUM(S10:S16)*IF($I$8="Real",1,T$5) -> 0 | T17: =SUM(T10:T16)*IF($I$8="Real",1,U$5) -> 0 | ... BE17: =SUM(BE10:BE16)*IF($I$8="Real",1,BF$5) -> 0
A19: Base Case (BC) | D19: ProjectId | E19: LifeCycleMonths | F19: Scenario | G19: ExpenseType | H19: Capex item | I19: Value basis | J19: Base year | K19: Applicant comment | L19: 2025 | M19: 2026 | N19: 2027 | O19: 2028 | P19: 2029 | Q19: 2030 | R19: 2031 | S19: 2032 | T19: 2033 | U19: 2034 | V19: 2035 | W19: 2036 | X19: 2037 | Y19: 2038 | Z19: 2039 | AA19: 2040 | AB19: 2041 | AC19: 2042 | AD19: 2043 | AE19: 2044 | AF19: 2045 | AG19: 2046 | AH19: 2047 | AI19: 2048 | AJ19: 2049 | AK19: 2050 | AL19: 2051 | AM19: 2052 | AN19: 2053 | AO19: 2054 | AP19: 2055 | AQ19: 2056 | AR19: 2057 | AS19: 2058 | AT19: 2059 | AU19: 2060 | AV19: 2061 | AW19: 2062 | AX19: 2063 | AY19: 2064 | AZ19: 2065 | BA19: 2066 | BB19: 2067 | BC19: 2068 | BD19: 2069 | BE19: 2070
A20: Expand if more items | D20: ='Project description'!$B$5 -> 0 | E20: =Lists!$B$34 | F20: BC | G20: capex | H20: Equipment purchase | I20: Real | J20: =Analysis_year -> 0 | K20: =IF(Inputs!G28="","",Inputs!G28) | L20: =Inputs!H28*IF(Inputs!$E28="Real",1,L$5) -> 0 | M20: =Inputs!I28*IF(Inputs!$E28="Real",1,M$5) -> 0 | N20: =Inputs!J28*IF(Inputs!$E28="Real",1,N$5) -> 0 | O20: =Inputs!K28*IF(Inputs!$E28="Real",1,O$5) -> 0 | P20: =Inputs!L28*IF(Inputs!$E28="Real",1,P$5) -> 0 | Q20: =Inputs!M28*IF(Inputs!$E28="Real",1,Q$5) -> 0 | R20: =Inputs!N28*IF(Inputs!$E28="Real",1,R$5) -> 0 | S20: =Inputs!O28*IF(Inputs!$E28="Real",1,S$5) -> 0 | ... BE20: =Inputs!BA28*IF(Inputs!$E28="Real",1,BE$5) -> 0
D21: ='Project description'!$B$5 -> 0 | E21: =Lists!$B$34 | F21: BC | G21: capex | H21: Civil works | I21: Real | J21: =Analysis_year -> 0 | K21: =IF(Inputs!G29="","",Inputs!G29) | L21: =Inputs!H29*IF(Inputs!$E29="Real",1,L$5) -> 0 | M21: =Inputs!I29*IF(Inputs!$E29="Real",1,M$5) -> 0 | N21: =Inputs!J29*IF(Inputs!$E29="Real",1,N$5) -> 0 | O21: =Inputs!K29*IF(Inputs!$E29="Real",1,O$5) -> 0 | P21: =Inputs!L29*IF(Inputs!$E29="Real",1,P$5) -> 0 | Q21: =Inputs!M29*IF(Inputs!$E29="Real",1,Q$5) -> 0 | R21: =Inputs!N29*IF(Inputs!$E29="Real",1,R$5) -> 0 | S21: =Inputs!O29*IF(Inputs!$E29="Real",1,S$5) -> 0 | ... BE21: =Inputs!BA29*IF(Inputs!$E29="Real",1,BE$5) -> 0
D22: ='Project description'!$B$5 -> 0 | E22: =Lists!$B$34 | F22: BC | G22: capex | H22: Electrical works | I22: Real | J22: =Analysis_year -> 0 | K22: =IF(Inputs!G30="","",Inputs!G30) | L22: =Inputs!H30*IF(Inputs!$E30="Real",1,L$5) -> 0 | M22: =Inputs!I30*IF(Inputs!$E30="Real",1,M$5) -> 0 | N22: =Inputs!J30*IF(Inputs!$E30="Real",1,N$5) -> 0 | O22: =Inputs!K30*IF(Inputs!$E30="Real",1,O$5) -> 0 | P22: =Inputs!L30*IF(Inputs!$E30="Real",1,P$5) -> 0 | Q22: =Inputs!M30*IF(Inputs!$E30="Real",1,Q$5) -> 0 | R22: =Inputs!N30*IF(Inputs!$E30="Real",1,R$5) -> 0 | S22: =Inputs!O30*IF(Inputs!$E30="Real",1,S$5) -> 0 | ... BE22: =Inputs!BA30*IF(Inputs!$E30="Real",1,BE$5) -> 0
D23: ='Project description'!$B$5 -> 0 | E23: =Lists!$B$34 | F23: BC | G23: capex | H23: Installation | I23: Real | J23: =Analysis_year -> 0 | K23: =IF(Inputs!G31="","",Inputs!G31) | L23: =Inputs!H31*IF(Inputs!$E31="Real",1,L$5) -> 0 | M23: =Inputs!I31*IF(Inputs!$E31="Real",1,M$5) -> 0 | N23: =Inputs!J31*IF(Inputs!$E31="Real",1,N$5) -> 0 | O23: =Inputs!K31*IF(Inputs!$E31="Real",1,O$5) -> 0 | P23: =Inputs!L31*IF(Inputs!$E31="Real",1,P$5) -> 0 | Q23: =Inputs!M31*IF(Inputs!$E31="Real",1,Q$5) -> 0 | R23: =Inputs!N31*IF(Inputs!$E31="Real",1,R$5) -> 0 | S23: =Inputs!O31*IF(Inputs!$E31="Real",1,S$5) -> 0 | ... BE23: =Inputs!BA31*IF(Inputs!$E31="Real",1,BE$5) -> 0
D24: ='Project description'!$B$5 -> 0 | E24: =Lists!$B$34 | F24: BC | G24: capex | H24: Indirect costs | I24: Real | J24: =Analysis_year -> 0 | K24: =IF(Inputs!G32="","",Inputs!G32) | L24: =Inputs!H32*IF(Inputs!$E32="Real",1,L$5) -> 0 | M24: =Inputs!I32*IF(Inputs!$E32="Real",1,M$5) -> 0 | N24: =Inputs!J32*IF(Inputs!$E32="Real",1,N$5) -> 0 | O24: =Inputs!K32*IF(Inputs!$E32="Real",1,O$5) -> 0 | P24: =Inputs!L32*IF(Inputs!$E32="Real",1,P$5) -> 0 | Q24: =Inputs!M32*IF(Inputs!$E32="Real",1,Q$5) -> 0 | R24: =Inputs!N32*IF(Inputs!$E32="Real",1,R$5) -> 0 | S24: =Inputs!O32*IF(Inputs!$E32="Real",1,S$5) -> 0 | ... BE24: =Inputs!BA32*IF(Inputs!$E32="Real",1,BE$5) -> 0
D25: ='Project description'!$B$5 -> 0 | E25: =Lists!$B$34 | F25: BC | G25: capex | H25: Project management | I25: Real | J25: =Analysis_year -> 0 | K25: =IF(Inputs!G33="","",Inputs!G33) | L25: =Inputs!H33*IF(Inputs!$E33="Real",1,L$5) -> 0 | M25: =Inputs!I33*IF(Inputs!$E33="Real",1,M$5) -> 0 | N25: =Inputs!J33*IF(Inputs!$E33="Real",1,N$5) -> 0 | O25: =Inputs!K33*IF(Inputs!$E33="Real",1,O$5) -> 0 | P25: =Inputs!L33*IF(Inputs!$E33="Real",1,P$5) -> 0 | Q25: =Inputs!M33*IF(Inputs!$E33="Real",1,Q$5) -> 0 | R25: =Inputs!N33*IF(Inputs!$E33="Real",1,R$5) -> 0 | S25: =Inputs!O33*IF(Inputs!$E33="Real",1,S$5) -> 0 | ... BE25: =Inputs!BA33*IF(Inputs!$E33="Real",1,BE$5) -> 0
D26: ='Project description'!$B$5 -> 0 | E26: =Lists!$B$34 | F26: BC | G26: capex | H26: Other | I26: Real | J26: =Analysis_year -> 0 | K26: =IF(Inputs!G34="","",Inputs!G34) | L26: =Inputs!H34*IF(Inputs!$E34="Real",1,L$5) -> 0 | M26: =Inputs!I34*IF(Inputs!$E34="Real",1,M$5) -> 0 | N26: =Inputs!J34*IF(Inputs!$E34="Real",1,N$5) -> 0 | O26: =Inputs!K34*IF(Inputs!$E34="Real",1,O$5) -> 0 | P26: =Inputs!L34*IF(Inputs!$E34="Real",1,P$5) -> 0 | Q26: =Inputs!M34*IF(Inputs!$E34="Real",1,Q$5) -> 0 | R26: =Inputs!N34*IF(Inputs!$E34="Real",1,R$5) -> 0 | S26: =Inputs!O34*IF(Inputs!$E34="Real",1,S$5) -> 0 | ... BE26: =Inputs!BA34*IF(Inputs!$E34="Real",1,BE$5) -> 0
H27: ="Total capex in "&Analysis_year&" dollars" -> Total capex in dollars | L27: =SUBTOTAL(109,'Real values'!$L$20:$L$26) -> 0 | M27: =SUBTOTAL(109,'Real values'!$M$20:$M$26) -> 0 | N27: =SUBTOTAL(109,'Real values'!$N$20:$N$26) -> 0 | O27: =SUBTOTAL(109,'Real values'!$O$20:$O$26) -> 0 | P27: =SUBTOTAL(109,'Real values'!$P$20:$P$26) -> 0 | Q27: =SUBTOTAL(109,'Real values'!$Q$20:$Q$26) -> 0 | R27: =SUBTOTAL(109,'Real values'!$R$20:$R$26) -> 0 | S27: =SUBTOTAL(109,'Real values'!$S$20:$S$26) -> 0 | T27: =SUBTOTAL(109,'Real values'!$T$20:$T$26) -> 0 | U27: =SUBTOTAL(109,'Real values'!$U$20:$U$26) -> 0 | V27: =SUBTOTAL(109,'Real values'!$V$20:$V$26) -> 0 | W27: =SUBTOTAL(109,'Real values'!$W$20:$W$26) -> 0 | X27: =SUBTOTAL(109,'Real values'!$X$20:$X$26) -> 0 | Y27: =SUBTOTAL(109,'Real values'!$Y$20:$Y$26) -> 0 | Z27: =SUBTOTAL(109,'Real values'!$Z$20:$Z$26) -> 0 | AA27: =SUBTOTAL(109,'Real values'!$AA$20:$AA$26) -> 0 | AB27: =SUBTOTAL(109,'Real values'!$AB$20:$AB$26) -> 0 | AC27: =SUBTOTAL(109,'Real values'!$AC$20:$AC$26) -> 0 | AD27: =SUBTOTAL(109,'Real values'!$AD$20:$AD$26) -> 0 | AE27: =SUBTOTAL(109,'Real values'!$AE$20:$AE$26) -> 0 | AF27: =SUBTOTAL(109,'Real values'!$AF$20:$AF$26) -> 0 | AG27: =SUBTOTAL(109,'Real values'!$AG$20:$AG$26) -> 0 | AH27: =SUBTOTAL(109,'Real values'!$AH$20:$AH$26) -> 0 | AI27: =SUBTOTAL(109,'Real values'!$AI$20:$AI$26) -> 0 | AJ27: =SUBTOTAL(109,'Real values'!$AJ$20:$AJ$26) -> 0 | AK27: =SUBTOTAL(109,'Real values'!$AK$20:$AK$26) -> 0 | AL27: =SUBTOTAL(109,'Real values'!$AL$20:$AL$26) -> 0 | AM27: =SUBTOTAL(109,'Real values'!$AM$20:$AM$26) -> 0 | AN27: =SUBTOTAL(109,'Real values'!$AN$20:$AN$26) -> 0 | AO27: =SUBTOTAL(109,'Real values'!$AO$20:$AO$26) -> 0 | AP27: =SUBTOTAL(109,'Real values'!$AP$20:$AP$26) -> 0 | AQ27: =SUBTOTAL(109,'Real values'!$AQ$20:$AQ$26) -> 0 | AR27: =SUBTOTAL(109,'Real values'!$AR$20:$AR$26) -> 0 | AS27: =SUBTOTAL(109,'Real values'!$AS$20:$AS$26) -> 0 | AT27: =SUBTOTAL(109,'Real values'!$AT$20:$AT$26) -> 0 | AU27: =SUBTOTAL(109,'Real values'!$AU$20:$AU$26) -> 0 | AV27: =SUBTOTAL(109,'Real values'!$AV$20:$AV$26) -> 0 | AW27: =SUBTOTAL(109,'Real values'!$AW$20:$AW$26) -> 0 | AX27: =SUBTOTAL(109,'Real values'!$AX$20:$AX$26) -> 0 | AY27: =SUBTOTAL(109,'Real values'!$AY$20:$AY$26) -> 0 | AZ27: =SUBTOTAL(109,'Real values'!$AZ$20:$AZ$26) -> 0 | BA27: =SUBTOTAL(109,'Real values'!$BA$20:$BA$26) -> 0 | BB27: =SUBTOTAL(109,'Real values'!$BB$20:$BB$26) -> 0 | BC27: =SUBTOTAL(109,'Real values'!$BC$20:$BC$26) -> 0 | BD27: =SUBTOTAL(109,'Real values'!$BD$20:$BD$26) -> 0 | BE27: =SUBTOTAL(109,'Real values'!$BE$20:$BE$26) -> 0
A29: 2) Operating & Maintenance Expenditure (OPEX) ($) - please enter all costs as positive numbers
A30: 2a) Non-fuel opex
A31: Proposed Project (PP) | D31: ProjectId | E31: LifeCycleMonths | F31: Scenario | G31: ExpenseType | H31: Opex item | I31: Value basis | J31: Base year | K31: Applicant comment | L31: 2025 | M31: 2026 | N31: 2027 | O31: 2028 | P31: 2029 | Q31: 2030 | R31: 2031 | S31: 2032 | T31: 2033 | U31: 2034 | V31: 2035 | W31: 2036 | X31: 2037 | Y31: 2038 | Z31: 2039 | AA31: 2040 | AB31: 2041 | AC31: 2042 | AD31: 2043 | AE31: 2044 | AF31: 2045 | AG31: 2046 | AH31: 2047 | AI31: 2048 | AJ31: 2049 | AK31: 2050 | AL31: 2051 | AM31: 2052 | AN31: 2053 | AO31: 2054 | AP31: 2055 | AQ31: 2056 | AR31: 2057 | AS31: 2058 | AT31: 2059 | AU31: 2060 | AV31: 2061 | AW31: 2062 | AX31: 2063 | AY31: 2064 | AZ31: 2065 | BA31: 2066 | BB31: 2067 | BC31: 2068 | BD31: 2069 | BE31: 2070
D32: ='Project description'!$B$5 -> 0 | E32: =Lists!$B$34 | F32: PP | G32: opex | H32: Equipment Operation Costs | I32: Real | J32: =Analysis_year -> 0 | K32: =IF(Inputs!G42="","",Inputs!G42) | L32: =Inputs!H42*IF(Inputs!$E42="Real",1,L$5) -> 0 | M32: =Inputs!I42*IF(Inputs!$E42="Real",1,M$5) -> 0 | N32: =Inputs!J42*IF(Inputs!$E42="Real",1,N$5) -> 0 | O32: =Inputs!K42*IF(Inputs!$E42="Real",1,O$5) -> 0 | P32: =Inputs!L42*IF(Inputs!$E42="Real",1,P$5) -> 0 | Q32: =Inputs!M42*IF(Inputs!$E42="Real",1,Q$5) -> 0 | R32: =Inputs!N42*IF(Inputs!$E42="Real",1,R$5) -> 0 | S32: =Inputs!O42*IF(Inputs!$E42="Real",1,S$5) -> 0 | ... BE32: =Inputs!BA42*IF(Inputs!$E42="Real",1,BE$5) -> 0
D33: ='Project description'!$B$5 -> 0 | E33: =Lists!$B$34 | F33: PP | G33: opex | H33: Maintenance, Repairs, Inspections | I33: Real | J33: =Analysis_year -> 0 | K33: =IF(Inputs!G43="","",Inputs!G43) | L33: =Inputs!H43*IF(Inputs!$E43="Real",1,L$5) -> 0 | M33: =Inputs!I43*IF(Inputs!$E43="Real",1,M$5) -> 0 | N33: =Inputs!J43*IF(Inputs!$E43="Real",1,N$5) -> 0 | O33: =Inputs!K43*IF(Inputs!$E43="Real",1,O$5) -> 0 | P33: =Inputs!L43*IF(Inputs!$E43="Real",1,P$5) -> 0 | Q33: =Inputs!M43*IF(Inputs!$E43="Real",1,Q$5) -> 0 | R33: =Inputs!N43*IF(Inputs!$E43="Real",1,R$5) -> 0 | S33: =Inputs!O43*IF(Inputs!$E43="Real",1,S$5) -> 0 | ... BE33: =Inputs!BA43*IF(Inputs!$E43="Real",1,BE$5) -> 0
D34: ='Project description'!$B$5 -> 0 | E34: =Lists!$B$34 | F34: PP | G34: opex | H34: Compliance Testing | I34: Real | J34: =Analysis_year -> 0 | K34: =IF(Inputs!G44="","",Inputs!G44) | L34: =Inputs!H44*IF(Inputs!$E44="Real",1,L$5) -> 0 | M34: =Inputs!I44*IF(Inputs!$E44="Real",1,M$5) -> 0 | N34: =Inputs!J44*IF(Inputs!$E44="Real",1,N$5) -> 0 | O34: =Inputs!K44*IF(Inputs!$E44="Real",1,O$5) -> 0 | P34: =Inputs!L44*IF(Inputs!$E44="Real",1,P$5) -> 0 | Q34: =Inputs!M44*IF(Inputs!$E44="Real",1,Q$5) -> 0 | R34: =Inputs!N44*IF(Inputs!$E44="Real",1,R$5) -> 0 | S34: =Inputs!O44*IF(Inputs!$E44="Real",1,S$5) -> 0 | ... BE34: =Inputs!BA44*IF(Inputs!$E44="Real",1,BE$5) -> 0
D35: ='Project description'!$B$5 -> 0 | E35: =Lists!$B$34 | F35: PP | G35: opex | H35: Optimisation | I35: Real | J35: =Analysis_year -> 0 | K35: =IF(Inputs!G45="","",Inputs!G45) | L35: =Inputs!H45*IF(Inputs!$E45="Real",1,L$5) -> 0 | M35: =Inputs!I45*IF(Inputs!$E45="Real",1,M$5) -> 0 | N35: =Inputs!J45*IF(Inputs!$E45="Real",1,N$5) -> 0 | O35: =Inputs!K45*IF(Inputs!$E45="Real",1,O$5) -> 0 | P35: =Inputs!L45*IF(Inputs!$E45="Real",1,P$5) -> 0 | Q35: =Inputs!M45*IF(Inputs!$E45="Real",1,Q$5) -> 0 | R35: =Inputs!N45*IF(Inputs!$E45="Real",1,R$5) -> 0 | S35: =Inputs!O45*IF(Inputs!$E45="Real",1,S$5) -> 0 | ... BE35: =Inputs!BA45*IF(Inputs!$E45="Real",1,BE$5) -> 0
D36: ='Project description'!$B$5 -> 0 | E36: =Lists!$B$34 | F36: PP | G36: opex | H36: Utilities and Consumables | I36: Real | J36: =Analysis_year -> 0 | K36: =IF(Inputs!G46="","",Inputs!G46) | L36: =Inputs!H46*IF(Inputs!$E46="Real",1,L$5) -> 0 | M36: =Inputs!I46*IF(Inputs!$E46="Real",1,M$5) -> 0 | N36: =Inputs!J46*IF(Inputs!$E46="Real",1,N$5) -> 0 | O36: =Inputs!K46*IF(Inputs!$E46="Real",1,O$5) -> 0 | P36: =Inputs!L46*IF(Inputs!$E46="Real",1,P$5) -> 0 | Q36: =Inputs!M46*IF(Inputs!$E46="Real",1,Q$5) -> 0 | R36: =Inputs!N46*IF(Inputs!$E46="Real",1,R$5) -> 0 | S36: =Inputs!O46*IF(Inputs!$E46="Real",1,S$5) -> 0 | ... BE36: =Inputs!BA46*IF(Inputs!$E46="Real",1,BE$5) -> 0
D37: ='Project description'!$B$5 -> 0 | E37: =Lists!$B$34 | F37: PP | G37: opex | H37: Other | I37: Real | J37: =Analysis_year -> 0 | K37: =IF(Inputs!G47="","",Inputs!G47) | L37: =Inputs!H47*IF(Inputs!$E47="Real",1,L$5) -> 0 | M37: =Inputs!I47*IF(Inputs!$E47="Real",1,M$5) -> 0 | N37: =Inputs!J47*IF(Inputs!$E47="Real",1,N$5) -> 0 | O37: =Inputs!K47*IF(Inputs!$E47="Real",1,O$5) -> 0 | P37: =Inputs!L47*IF(Inputs!$E47="Real",1,P$5) -> 0 | Q37: =Inputs!M47*IF(Inputs!$E47="Real",1,Q$5) -> 0 | R37: =Inputs!N47*IF(Inputs!$E47="Real",1,R$5) -> 0 | S37: =Inputs!O47*IF(Inputs!$E47="Real",1,S$5) -> 0 | ... BE37: =Inputs!BA47*IF(Inputs!$E47="Real",1,BE$5) -> 0
H38: ="Total non-fuel opex in "&Analysis_year&" dollars" -> Total non-fuel opex in dollars | L38: =SUBTOTAL(109,'Real values'!$L$32:$L$37) -> 0 | M38: =SUBTOTAL(109,'Real values'!$M$32:$M$37) -> 0 | N38: =SUBTOTAL(109,'Real values'!$N$32:$N$37) -> 0 | O38: =SUBTOTAL(109,'Real values'!$O$32:$O$37) -> 0 | P38: =SUBTOTAL(109,'Real values'!$P$32:$P$37) -> 0 | Q38: =SUBTOTAL(109,'Real values'!$Q$32:$Q$37) -> 0 | R38: =SUBTOTAL(109,'Real values'!$R$32:$R$37) -> 0 | S38: =SUBTOTAL(109,'Real values'!$S$32:$S$37) -> 0 | T38: =SUBTOTAL(109,'Real values'!$T$32:$T$37) -> 0 | U38: =SUBTOTAL(109,'Real values'!$U$32:$U$37) -> 0 | V38: =SUBTOTAL(109,'Real values'!$V$32:$V$37) -> 0 | W38: =SUBTOTAL(109,'Real values'!$W$32:$W$37) -> 0 | X38: =SUBTOTAL(109,'Real values'!$X$32:$X$37) -> 0 | Y38: =SUBTOTAL(109,'Real values'!$Y$32:$Y$37) -> 0 | Z38: =SUBTOTAL(109,'Real values'!$Z$32:$Z$37) -> 0 | AA38: =SUBTOTAL(109,'Real values'!$AA$32:$AA$37) -> 0 | AB38: =SUBTOTAL(109,'Real values'!$AB$32:$AB$37) -> 0 | AC38: =SUBTOTAL(109,'Real values'!$AC$32:$AC$37) -> 0 | AD38: =SUBTOTAL(109,'Real values'!$AD$32:$AD$37) -> 0 | AE38: =SUBTOTAL(109,'Real values'!$AE$32:$AE$37) -> 0 | AF38: =SUBTOTAL(109,'Real values'!$AF$32:$AF$37) -> 0 | AG38: =SUBTOTAL(109,'Real values'!$AG$32:$AG$37) -> 0 | AH38: =SUBTOTAL(109,'Real values'!$AH$32:$AH$37) -> 0 | AI38: =SUBTOTAL(109,'Real values'!$AI$32:$AI$37) -> 0 | AJ38: =SUBTOTAL(109,'Real values'!$AJ$32:$AJ$37) -> 0 | AK38: =SUBTOTAL(109,'Real values'!$AK$32:$AK$37) -> 0 | AL38: =SUBTOTAL(109,'Real values'!$AL$32:$AL$37) -> 0 | AM38: =SUBTOTAL(109,'Real values'!$AM$32:$AM$37) -> 0 | AN38: =SUBTOTAL(109,'Real values'!$AN$32:$AN$37) -> 0 | AO38: =SUBTOTAL(109,'Real values'!$AO$32:$AO$37) -> 0 | AP38: =SUBTOTAL(109,'Real values'!$AP$32:$AP$37) -> 0 | AQ38: =SUBTOTAL(109,'Real values'!$AQ$32:$AQ$37) -> 0 | AR38: =SUBTOTAL(109,'Real values'!$AR$32:$AR$37) -> 0 | AS38: =SUBTOTAL(109,'Real values'!$AS$32:$AS$37) -> 0 | AT38: =SUBTOTAL(109,'Real values'!$AT$32:$AT$37) -> 0 | AU38: =SUBTOTAL(109,'Real values'!$AU$32:$AU$37) -> 0 | AV38: =SUBTOTAL(109,'Real values'!$AV$32:$AV$37) -> 0 | AW38: =SUBTOTAL(109,'Real values'!$AW$32:$AW$37) -> 0 | AX38: =SUBTOTAL(109,'Real values'!$AX$32:$AX$37) -> 0 | AY38: =SUBTOTAL(109,'Real values'!$AY$32:$AY$37) -> 0 | AZ38: =SUBTOTAL(109,'Real values'!$AZ$32:$AZ$37) -> 0 | BA38: =SUBTOTAL(109,'Real values'!$BA$32:$BA$37) -> 0 | BB38: =SUBTOTAL(109,'Real values'!$BB$32:$BB$37) -> 0 | BC38: =SUBTOTAL(109,'Real values'!$BC$32:$BC$37) -> 0 | BD38: =SUBTOTAL(109,'Real values'!$BD$32:$BD$37) -> 0 | BE38: =SUBTOTAL(109,'Real values'!$BE$32:$BE$37) -> 0
A40: Base Case (BC) | D40: ProjectId | E40: LifeCycleMonths | F40: Scenario | G40: ExpenseType | H40: Opex item | I40: Value basis | J40: Base year | K40: Applicant comment | L40: 2025 | M40: 2026 | N40: 2027 | O40: 2028 | P40: 2029 | Q40: 2030 | R40: 2031 | S40: 2032 | T40: 2033 | U40: 2034 | V40: 2035 | W40: 2036 | X40: 2037 | Y40: 2038 | Z40: 2039 | AA40: 2040 | AB40: 2041 | AC40: 2042 | AD40: 2043 | AE40: 2044 | AF40: 2045 | AG40: 2046 | AH40: 2047 | AI40: 2048 | AJ40: 2049 | AK40: 2050 | AL40: 2051 | AM40: 2052 | AN40: 2053 | AO40: 2054 | AP40: 2055 | AQ40: 2056 | AR40: 2057 | AS40: 2058 | AT40: 2059 | AU40: 2060 | AV40: 2061 | AW40: 2062 | AX40: 2063 | AY40: 2064 | AZ40: 2065 | BA40: 2066 | BB40: 2067 | BC40: 2068 | BD40: 2069 | BE40: 2070
D41: ='Project description'!$B$5 -> 0 | E41: =Lists!$B$34 | F41: BC | G41: opex | H41: Equipment Operation Costs | I41: Real | J41: =Analysis_year -> 0 | K41: =IF(Inputs!G53="","",Inputs!G53) | L41: =Inputs!H53*IF(Inputs!$E53="Real",1,L$5) -> 0 | M41: =Inputs!I53*IF(Inputs!$E53="Real",1,M$5) -> 0 | N41: =Inputs!J53*IF(Inputs!$E53="Real",1,N$5) -> 0 | O41: =Inputs!K53*IF(Inputs!$E53="Real",1,O$5) -> 0 | P41: =Inputs!L53*IF(Inputs!$E53="Real",1,P$5) -> 0 | Q41: =Inputs!M53*IF(Inputs!$E53="Real",1,Q$5) -> 0 | R41: =Inputs!N53*IF(Inputs!$E53="Real",1,R$5) -> 0 | S41: =Inputs!O53*IF(Inputs!$E53="Real",1,S$5) -> 0 | ... BE41: =Inputs!BA53*IF(Inputs!$E53="Real",1,BE$5) -> 0
D42: ='Project description'!$B$5 -> 0 | E42: =Lists!$B$34 | F42: BC | G42: opex | H42: Maintenance, Repairs, Inspections | I42: Real | J42: =Analysis_year -> 0 | K42: =IF(Inputs!G54="","",Inputs!G54) | L42: =Inputs!H54*IF(Inputs!$E54="Real",1,L$5) -> 0 | M42: =Inputs!I54*IF(Inputs!$E54="Real",1,M$5) -> 0 | N42: =Inputs!J54*IF(Inputs!$E54="Real",1,N$5) -> 0 | O42: =Inputs!K54*IF(Inputs!$E54="Real",1,O$5) -> 0 | P42: =Inputs!L54*IF(Inputs!$E54="Real",1,P$5) -> 0 | Q42: =Inputs!M54*IF(Inputs!$E54="Real",1,Q$5) -> 0 | R42: =Inputs!N54*IF(Inputs!$E54="Real",1,R$5) -> 0 | S42: =Inputs!O54*IF(Inputs!$E54="Real",1,S$5) -> 0 | ... BE42: =Inputs!BA54*IF(Inputs!$E54="Real",1,BE$5) -> 0
D43: ='Project description'!$B$5 -> 0 | E43: =Lists!$B$34 | F43: BC | G43: opex | H43: Compliance Testing | I43: Real | J43: =Analysis_year -> 0 | K43: =IF(Inputs!G55="","",Inputs!G55) | L43: =Inputs!H55*IF(Inputs!$E55="Real",1,L$5) -> 0 | M43: =Inputs!I55*IF(Inputs!$E55="Real",1,M$5) -> 0 | N43: =Inputs!J55*IF(Inputs!$E55="Real",1,N$5) -> 0 | O43: =Inputs!K55*IF(Inputs!$E55="Real",1,O$5) -> 0 | P43: =Inputs!L55*IF(Inputs!$E55="Real",1,P$5) -> 0 | Q43: =Inputs!M55*IF(Inputs!$E55="Real",1,Q$5) -> 0 | R43: =Inputs!N55*IF(Inputs!$E55="Real",1,R$5) -> 0 | S43: =Inputs!O55*IF(Inputs!$E55="Real",1,S$5) -> 0 | ... BE43: =Inputs!BA55*IF(Inputs!$E55="Real",1,BE$5) -> 0
D44: ='Project description'!$B$5 -> 0 | E44: =Lists!$B$34 | F44: BC | G44: opex | H44: Optimisation | I44: Real | J44: =Analysis_year -> 0 | K44: =IF(Inputs!G56="","",Inputs!G56) | L44: =Inputs!H56*IF(Inputs!$E56="Real",1,L$5) -> 0 | M44: =Inputs!I56*IF(Inputs!$E56="Real",1,M$5) -> 0 | N44: =Inputs!J56*IF(Inputs!$E56="Real",1,N$5) -> 0 | O44: =Inputs!K56*IF(Inputs!$E56="Real",1,O$5) -> 0 | P44: =Inputs!L56*IF(Inputs!$E56="Real",1,P$5) -> 0 | Q44: =Inputs!M56*IF(Inputs!$E56="Real",1,Q$5) -> 0 | R44: =Inputs!N56*IF(Inputs!$E56="Real",1,R$5) -> 0 | S44: =Inputs!O56*IF(Inputs!$E56="Real",1,S$5) -> 0 | ... BE44: =Inputs!BA56*IF(Inputs!$E56="Real",1,BE$5) -> 0
D45: ='Project description'!$B$5 -> 0 | E45: =Lists!$B$34 | F45: BC | G45: opex | H45: Utilities and Consumables | I45: Real | J45: =Analysis_year -> 0 | K45: =IF(Inputs!G57="","",Inputs!G57) | L45: =Inputs!H57*IF(Inputs!$E57="Real",1,L$5) -> 0 | M45: =Inputs!I57*IF(Inputs!$E57="Real",1,M$5) -> 0 | N45: =Inputs!J57*IF(Inputs!$E57="Real",1,N$5) -> 0 | O45: =Inputs!K57*IF(Inputs!$E57="Real",1,O$5) -> 0 | P45: =Inputs!L57*IF(Inputs!$E57="Real",1,P$5) -> 0 | Q45: =Inputs!M57*IF(Inputs!$E57="Real",1,Q$5) -> 0 | R45: =Inputs!N57*IF(Inputs!$E57="Real",1,R$5) -> 0 | S45: =Inputs!O57*IF(Inputs!$E57="Real",1,S$5) -> 0 | ... BE45: =Inputs!BA57*IF(Inputs!$E57="Real",1,BE$5) -> 0
D46: ='Project description'!$B$5 -> 0 | E46: =Lists!$B$34 | F46: BC | G46: opex | H46: Other | I46: Real | J46: =Analysis_year -> 0 | K46: =IF(Inputs!G58="","",Inputs!G58) | L46: =Inputs!H58*IF(Inputs!$E58="Real",1,L$5) -> 0 | M46: =Inputs!I58*IF(Inputs!$E58="Real",1,M$5) -> 0 | N46: =Inputs!J58*IF(Inputs!$E58="Real",1,N$5) -> 0 | O46: =Inputs!K58*IF(Inputs!$E58="Real",1,O$5) -> 0 | P46: =Inputs!L58*IF(Inputs!$E58="Real",1,P$5) -> 0 | Q46: =Inputs!M58*IF(Inputs!$E58="Real",1,Q$5) -> 0 | R46: =Inputs!N58*IF(Inputs!$E58="Real",1,R$5) -> 0 | S46: =Inputs!O58*IF(Inputs!$E58="Real",1,S$5) -> 0 | ... BE46: =Inputs!BA58*IF(Inputs!$E58="Real",1,BE$5) -> 0
...

Sheet Results
A1: ='Project description'!B4 -> <Select> | B1: Years from start: | C1: =Analysis_year-Start_Yr -> 0
A3: National perspective
A4: NPV | B4: 2% | C4: 8%
A5: PP | B5: =Calculations!F65 -> 0 | C5: =Calculations!G65 -> 0
A6: BC | B6: =Calculations!F66 -> 0 | C6: =Calculations!G66 -> 0
A7: Preferred: | B7: =IF(B5>B6,$A5,$A6) -> BC | C7: =IF(C5>C6,$A5,$A6) -> BC
A10: Private perspective
A11: Private Returns | B11: Pre-tax Nominal | C11: IRR
B12: =ReturnType -> <Select>
A13: PP | B13: =Calculations!E76 -> 0 | C13: =Calculations!F76 -> No feasible solution
A14: BC | B14: =Calculations!E77 -> 0 | C14: =Calculations!F77 -> No feasible solution
A15: Preferred: | B15: =IF(B13>B14,$A13,$A14) -> BC | C15: =IF(C13>C14,$A13,$A14) -> BC
A18: Energy savings (GJ) | B18: Total | C18: 2025 | D18: 2026 | E18: 2027 | F18: 2028 | G18: 2029 | H18: 2030 | I18: 2031 | J18: 2032 | K18: 2033 | L18: 2034 | M18: 2035 | N18: 2036 | O18: 2037 | P18: 2038 | Q18: 2039 | R18: 2040 | S18: 2041 | T18: 2042 | U18: 2043 | V18: 2044 | W18: 2045 | X18: 2046 | Y18: 2047 | Z18: 2048 | AA18: 2049 | AB18: 2050 | AC18: 2051 | AD18: 2052 | AE18: 2053 | AF18: 2054 | AG18: 2055 | AH18: 2056 | AI18: 2057 | AJ18: 2058 | AK18: 2059 | AL18: 2060 | AM18: 2061 | AN18: 2062 | AO18: 2063 | AP18: 2064 | AQ18: 2065 | AR18: 2066 | AS18: 2067 | AT18: 2068 | AU18: 2069 | AV18: 2070
A19: Electricity | B19: =SUM(C19:AU19) -> 0 | C19: ='Real values'!L64-'Real values'!L51 -> 0 | D19: ='Real values'!M64-'Real values'!M51 -> 0 | E19: ='Real values'!N64-'Real values'!N51 -> 0 | F19: ='Real values'!O64-'Real values'!O51 -> 0 | G19: ='Real values'!P64-'Real values'!P51 -> 0 | H19: ='Real values'!Q64-'Real values'!Q51 -> 0 | I19: ='Real values'!R64-'Real values'!R51 -> 0 | J19: ='Real values'!S64-'Real values'!S51 -> 0 | ... AR19: ='Real values'!BA64-'Real values'!BA51 -> 0 | AS19: ='Real values'!BC64-'Real values'!BC51 -> 0 | AT19: ='Real values'!BD64-'Real values'!BD51 -> 0 | AU19: ='Real values'!BE64-'Real values'!BE51 -> 0 | AV19: ='Real values'!BF64-'Real values'!BF51 -> 0
A20: Natural Gas | B20: =SUM(C20:AU20) -> 0 | C20: ='Real values'!L65-'Real values'!L52 -> 0 | D20: ='Real values'!M65-'Real values'!M52 -> 0 | E20: ='Real values'!N65-'Real values'!N52 -> 0 | F20: ='Real values'!O65-'Real values'!O52 -> 0 | G20: ='Real values'!P65-'Real values'!P52 -> 0 | H20: ='Real values'!Q65-'Real values'!Q52 -> 0 | I20: ='Real values'!R65-'Real values'!R52 -> 0 | J20: ='Real values'!S65-'Real values'!S52 -> 0 | ... AR20: ='Real values'!BA65-'Real values'!BA52 -> 0 | AS20: ='Real values'!BC65-'Real values'!BC52 -> 0 | AT20: ='Real values'!BD65-'Real values'!BD52 -> 0 | AU20: ='Real values'!BE65-'Real values'!BE52 -> 0 | AV20: ='Real values'!BF65-'Real values'!BF52 -> 0
A21: Coal - sub bituminous | B21: =SUM(C21:AU21) -> 0 | C21: ='Real values'!L66-'Real values'!L53 -> 0 | D21: ='Real values'!M66-'Real values'!M53 -> 0 | E21: ='Real values'!N66-'Real values'!N53 -> 0 | F21: ='Real values'!O66-'Real values'!O53 -> 0 | G21: ='Real values'!P66-'Real values'!P53 -> 0 | H21: ='Real values'!Q66-'Real values'!Q53 -> 0 | I21: ='Real values'!R66-'Real values'!R53 -> 0 | J21: ='Real values'!S66-'Real values'!S53 -> 0 | ... AR21: ='Real values'!BA66-'Real values'!BA53 -> 0 | AS21: ='Real values'!BC66-'Real values'!BC53 -> 0 | AT21: ='Real values'!BD66-'Real values'!BD53 -> 0 | AU21: ='Real values'!BE66-'Real values'!BE53 -> 0 | AV21: ='Real values'!BF66-'Real values'!BF53 -> 0
A22: Coal - bituminous | B22: =SUM(C22:AU22) -> 0 | C22: ='Real values'!L67-'Real values'!L54 -> 0 | D22: ='Real values'!M67-'Real values'!M54 -> 0 | E22: ='Real values'!N67-'Real values'!N54 -> 0 | F22: ='Real values'!O67-'Real values'!O54 -> 0 | G22: ='Real values'!P67-'Real values'!P54 -> 0 | H22: ='Real values'!Q67-'Real values'!Q54 -> 0 | I22: ='Real values'!R67-'Real values'!R54 -> 0 | J22: ='Real values'!S67-'Real values'!S54 -> 0 | ... AR22: ='Real values'!BA67-'Real values'!BA54 -> 0 | AS22: ='Real values'!BC67-'Real values'!BC54 -> 0 | AT22: ='Real values'!BD67-'Real values'!BD54 -> 0 | AU22: ='Real values'!BE67-'Real values'!BE54 -> 0 | AV22: ='Real values'!BF67-'Real values'!BF54 -> 0
A23: Coal - lignite | B23: =SUM(C23:AU23) -> 0 | C23: ='Real values'!L68-'Real values'!L55 -> 0 | D23: ='Real values'!M68-'Real values'!M55 -> 0 | E23: ='Real values'!N68-'Real values'!N55 -> 0 | F23: ='Real values'!O68-'Real values'!O55 -> 0 | G23: ='Real values'!P68-'Real values'!P55 -> 0 | H23: ='Real values'!Q68-'Real values'!Q55 -> 0 | I23: ='Real values'!R68-'Real values'!R55 -> 0 | J23: ='Real values'!S68-'Real values'!S55 -> 0 | ... AR23: ='Real values'!BA68-'Real values'!BA55 -> 0 | AS23: ='Real values'!BC68-'Real values'!BC55 -> 0 | AT23: ='Real values'!BD68-'Real values'!BD55 -> 0 | AU23: ='Real values'!BE68-'Real values'!BE55 -> 0 | AV23: ='Real values'!BF68-'Real values'!BF55 -> 0
A24: Diesel | B24: =SUM(C24:AU24) -> 0 | C24: ='Real values'!L69-'Real values'!L56 -> 0 | D24: ='Real values'!M69-'Real values'!M56 -> 0 | E24: ='Real values'!N69-'Real values'!N56 -> 0 | F24: ='Real values'!O69-'Real values'!O56 -> 0 | G24: ='Real values'!P69-'Real values'!P56 -> 0 | H24: ='Real values'!Q69-'Real values'!Q56 -> 0 | I24: ='Real values'!R69-'Real values'!R56 -> 0 | J24: ='Real values'!S69-'Real values'!S56 -> 0 | ... AR24: ='Real values'!BA69-'Real values'!BA56 -> 0 | AS24: ='Real values'!BC69-'Real values'!BC56 -> 0 | AT24: ='Real values'!BD69-'Real values'!BD56 -> 0 | AU24: ='Real values'!BE69-'Real values'!BE56 -> 0 | AV24: ='Real values'!BF69-'Real values'!BF56 -> 0
A25: LPG | B25: =SUM(C25:AU25) -> 0 | C25: ='Real values'!L70-'Real values'!L57 -> 0 | D25: ='Real values'!M70-'Real values'!M57 -> 0 | E25: ='Real values'!N70-'Real values'!N57 -> 0 | F25: ='Real values'!O70-'Real values'!O57 -> 0 | G25: ='Real values'!P70-'Real values'!P57 -> 0 | H25: ='Real values'!Q70-'Real values'!Q57 -> 0 | I25: ='Real values'!R70-'Real values'!R57 -> 0 | J25: ='Real values'!S70-'Real values'!S57 -> 0 | ... AR25: ='Real values'!BA70-'Real values'!BA57 -> 0 | AS25: ='Real values'!BC70-'Real values'!BC57 -> 0 | AT25: ='Real values'!BD70-'Real values'!BD57 -> 0 | AU25: ='Real values'!BE70-'Real values'!BE57 -> 0 | AV25: ='Real values'!BF70-'Real values'!BF57 -> 0
A26: Light fuel oil | B26: =SUM(C26:AU26) -> 0 | C26: ='Real values'!L71-'Real values'!L58 -> 0 | D26: ='Real values'!M71-'Real values'!M58 -> 0 | E26: ='Real values'!N71-'Real values'!N58 -> 0 | F26: ='Real values'!O71-'Real values'!O58 -> 0 | G26: ='Real values'!P71-'Real values'!P58 -> 0 | H26: ='Real values'!Q71-'Real values'!Q58 -> 0 | I26: ='Real values'!R71-'Real values'!R58 -> 0 | J26: ='Real values'!S71-'Real values'!S58 -> 0 | ... AR26: ='Real values'!BA71-'Real values'!BA58 -> 0 | AS26: ='Real values'!BC71-'Real values'!BC58 -> 0 | AT26: ='Real values'!BD71-'Real values'!BD58 -> 0 | AU26: ='Real values'!BE71-'Real values'!BE58 -> 0 | AV26: ='Real values'!BF71-'Real values'!BF58 -> 0
A27: Heavy fuel oil | B27: =SUM(C27:AU27) -> 0 | C27: ='Real values'!L72-'Real values'!L59 -> 0 | D27: ='Real values'!M72-'Real values'!M59 -> 0 | E27: ='Real values'!N72-'Real values'!N59 -> 0 | F27: ='Real values'!O72-'Real values'!O59 -> 0 | G27: ='Real values'!P72-'Real values'!P59 -> 0 | H27: ='Real values'!Q72-'Real values'!Q59 -> 0 | I27: ='Real values'!R72-'Real values'!R59 -> 0 | J27: ='Real values'!S72-'Real values'!S59 -> 0 | ... AR27: ='Real values'!BA72-'Real values'!BA59 -> 0 | AS27: ='Real values'!BC72-'Real values'!BC59 -> 0 | AT27: ='Real values'!BD72-'Real values'!BD59 -> 0 | AU27: ='Real values'!BE72-'Real values'!BE59 -> 0 | AV27: ='Real values'!BF72-'Real values'!BF59 -> 0
A28: Geothermal | B28: =SUM(C28:AU28) -> 0 | C28: ='Real values'!L73-'Real values'!L60 -> 0 | D28: ='Real values'!M73-'Real values'!M60 -> 0 | E28: ='Real values'!N73-'Real values'!N60 -> 0 | F28: ='Real values'!O73-'Real values'!O60 -> 0 | G28: ='Real values'!P73-'Real values'!P60 -> 0 | H28: ='Real values'!Q73-'Real values'!Q60 -> 0 | I28: ='Real values'!R73-'Real values'!R60 -> 0 | J28: ='Real values'!S73-'Real values'!S60 -> 0 | ... AR28: ='Real values'!BA73-'Real values'!BA60 -> 0 | AS28: ='Real values'!BC73-'Real values'!BC60 -> 0 | AT28: ='Real values'!BD73-'Real values'!BD60 -> 0 | AU28: ='Real values'!BE73-'Real values'!BE60 -> 0 | AV28: ='Real values'!BF73-'Real values'!BF60 -> 0
A29: Wood or wood chips | B29: =SUM(C29:AU29) -> 0 | C29: ='Real values'!L74-'Real values'!L61 -> 0 | D29: ='Real values'!M74-'Real values'!M61 -> 0 | E29: ='Real values'!N74-'Real values'!N61 -> 0 | F29: ='Real values'!O74-'Real values'!O61 -> 0 | G29: ='Real values'!P74-'Real values'!P61 -> 0 | H29: ='Real values'!Q74-'Real values'!Q61 -> 0 | I29: ='Real values'!R74-'Real values'!R61 -> 0 | J29: ='Real values'!S74-'Real values'!S61 -> 0 | ... AR29: ='Real values'!BA74-'Real values'!BA61 -> 0 | AS29: ='Real values'!BC74-'Real values'!BC61 -> 0 | AT29: ='Real values'!BD74-'Real values'!BD61 -> 0 | AU29: ='Real values'!BE74-'Real values'!BE61 -> 0 | AV29: ='Real values'!BF74-'Real values'!BF61 -> 0
A30: Total | B30: =SUM(B19:B29) -> 0 | C30: =SUM(C19:C29) -> 0 | D30: =SUM(D19:D29) -> 0 | E30: =SUM(E19:E29) -> 0 | F30: =SUM(F19:F29) -> 0 | G30: =SUM(G19:G29) -> 0 | H30: =SUM(H19:H29) -> 0 | I30: =SUM(I19:I29) -> 0 | ... AV30: =SUM(AV19:AV29) -> 0
A32: Energy savings ($) | B32: Total | C32: 2025 | D32: 2026 | E32: 2027 | F32: 2028 | G32: 2029 | H32: 2030 | I32: 2031 | J32: 2032 | K32: 2033 | L32: 2034 | M32: 2035 | N32: 2036 | O32: 2037 | P32: 2038 | Q32: 2039 | R32: 2040 | S32: 2041 | T32: 2042 | U32: 2043 | V32: 2044 | W32: 2045 | X32: 2046 | Y32: 2047 | Z32: 2048 | AA32: 2049 | AB32: 2050 | AC32: 2051 | AD32: 2052 | AE32: 2053 | AF32: 2054 | AG32: 2055 | AH32: 2056 | AI32: 2057 | AJ32: 2058 | AK32: 2059 | AL32: 2060 | AM32: 2061 | AN32: 2062 | AO32: 2063 | AP32: 2064 | AQ32: 2065 | AR32: 2066 | AS32: 2067 | AT32: 2068 | AU32: 2069 | AV32: 2070
A33: Electricity | B33: =SUM(C33:AU33) -> 0 | C33: ='Real values'!L119-'Real values'!L105 -> 0 | D33: ='Real values'!M119-'Real values'!M105 -> 0 | E33: ='Real values'!N119-'Real values'!N105 -> 0 | F33: ='Real values'!O119-'Real values'!O105 -> 0 | G33: ='Real values'!P119-'Real values'!P105 -> 0 | H33: ='Real values'!Q119-'Real values'!Q105 -> 0 | I33: ='Real values'!R119-'Real values'!R105 -> 0 | J33: ='Real values'!S119-'Real values'!S105 -> 0 | ... AP33: ='Real values'!AY119-'Real values'!AY105 -> 0 | AQ33: ='Real values'!BA119-'Real values'!BA105 -> 0 | AR33: ='Real values'!BB119-'Real values'!BB105 -> 0 | AS33: ='Real values'!BC119-'Real values'!BC105 -> 0 | AT33: ='Real values'!BD119-'Real values'!BD105 -> 0 | AU33: ='Real values'!BE119-'Real values'!BE105 -> 0 | AV33: ='Real values'!BF119-'Real values'!BF105 -> 0
A34: Natural Gas | B34: =SUM(C34:AU34) -> 0 | C34: ='Real values'!L120-'Real values'!L106 -> 0 | D34: ='Real values'!M120-'Real values'!M106 -> 0 | E34: ='Real values'!N120-'Real values'!N106 -> 0 | F34: ='Real values'!O120-'Real values'!O106 -> 0 | G34: ='Real values'!P120-'Real values'!P106 -> 0 | H34: ='Real values'!Q120-'Real values'!Q106 -> 0 | I34: ='Real values'!R120-'Real values'!R106 -> 0 | J34: ='Real values'!S120-'Real values'!S106 -> 0 | ... AP34: ='Real values'!AY120-'Real values'!AY106 -> 0 | AQ34: ='Real values'!BA120-'Real values'!BA106 -> 0 | AR34: ='Real values'!BB120-'Real values'!BB106 -> 0 | AS34: ='Real values'!BC120-'Real values'!BC106 -> 0 | AT34: ='Real values'!BD120-'Real values'!BD106 -> 0 | AU34: ='Real values'!BE120-'Real values'!BE106 -> 0 | AV34: ='Real values'!BF120-'Real values'!BF106 -> 0
A35: Coal - sub bituminous | B35: =SUM(C35:AU35) -> 0 | C35: ='Real values'!L121-'Real values'!L107 -> 0 | D35: ='Real values'!M121-'Real values'!M107 -> 0 | E35: ='Real values'!N121-'Real values'!N107 -> 0 | F35: ='Real values'!O121-'Real values'!O107 -> 0 | G35: ='Real values'!P121-'Real values'!P107 -> 0 | H35: ='Real values'!Q121-'Real values'!Q107 -> 0 | I35: ='Real values'!R121-'Real values'!R107 -> 0 | J35: ='Real values'!S121-'Real values'!S107 -> 0 | ... AP35: ='Real values'!AY121-'Real values'!AY107 -> 0 | AQ35: ='Real values'!BA121-'Real values'!BA107 -> 0 | AR35: ='Real values'!BB121-'Real values'!BB107 -> 0 | AS35: ='Real values'!BC121-'Real values'!BC107 -> 0 | AT35: ='Real values'!BD121-'Real values'!BD107 -> 0 | AU35: ='Real values'!BE121-'Real values'!BE107 -> 0 | AV35: ='Real values'!BF121-'Real values'!BF107 -> 0
A36: Coal - bituminous | B36: =SUM(C36:AU36) -> 0 | C36: ='Real values'!L122-'Real values'!L108 -> 0 | D36: ='Real values'!M122-'Real values'!M108 -> 0 | E36: ='Real values'!N122-'Real values'!N108 -> 0 | F36: ='Real values'!O122-'Real values'!O108 -> 0 | G36: ='Real values'!P122-'Real values'!P108 -> 0 | H36: ='Real values'!Q122-'Real values'!Q108 -> 0 | I36: ='Real values'!R122-'Real values'!R108 -> 0 | J36: ='Real values'!S122-'Real values'!S108 -> 0 | ... AP36: ='Real values'!AY122-'Real values'!AY108 -> 0 | AQ36: ='Real values'!BA122-'Real values'!BA108 -> 0 | AR36: ='Real values'!BB122-'Real values'!BB108 -> 0 | AS36: ='Real values'!BC122-'Real values'!BC108 -> 0 | AT36: ='Real values'!BD122-'Real values'!BD108 -> 0 | AU36: ='Real values'!BE122-'Real values'!BE108 -> 0 | AV36: ='Real values'!BF122-'Real values'!BF108 -> 0
A37: Coal - lignite | B37: =SUM(C37:AU37) -> 0 | C37: ='Real values'!L123-'Real values'!L109 -> 0 | D37: ='Real values'!M123-'Real values'!M109 -> 0 | E37: ='Real values'!N123-'Real values'!N109 -> 0 | F37: ='Real values'!O123-'Real values'!O109 -> 0 | G37: ='Real values'!P123-'Real values'!P109 -> 0 | H37: ='Real values'!Q123-'Real values'!Q109 -> 0 | I37: ='Real values'!R123-'Real values'!R109 -> 0 | J37: ='Real values'!S123-'Real values'!S109 -> 0 | ... AP37: ='Real values'!AY123-'Real values'!AY109 -> 0 | AQ37: ='Real values'!BA123-'Real values'!BA109 -> 0 | AR37: ='Real values'!BB123-'Real values'!BB109 -> 0 | AS37: ='Real values'!BC123-'Real values'!BC109 -> 0 | AT37: ='Real values'!BD123-'Real values'!BD109 -> 0 | AU37: ='Real values'!BE123-'Real values'!BE109 -> 0 | AV37: ='Real values'!BF123-'Real values'!BF109 -> 0
A38: Diesel | B38: =SUM(C38:AU38) -> 0 | C38: ='Real values'!L124-'Real values'!L110 -> 0 | D38: ='Real values'!M124-'Real values'!M110 -> 0 | E38: ='Real values'!N124-'Real values'!N110 -> 0 | F38: ='Real values'!O124-'Real values'!O110 -> 0 | G38: ='Real values'!P124-'Real values'!P110 -> 0 | H38: ='Real values'!Q124-'Real values'!Q110 -> 0 | I38: ='Real values'!R124-'Real values'!R110 -> 0 | J38: ='Real values'!S124-'Real values'!S110 -> 0 | ... AP38: ='Real values'!AY124-'Real values'!AY110 -> 0 | AQ38: ='Real values'!BA124-'Real values'!BA110 -> 0 | AR38: ='Real values'!BB124-'Real values'!BB110 -> 0 | AS38: ='Real values'!BC124-'Real values'!BC110 -> 0 | AT38: ='Real values'!BD124-'Real values'!BD110 -> 0 | AU38: ='Real values'!BE124-'Real values'!BE110 -> 0 | AV38: ='Real values'!BF124-'Real values'!BF110 -> 0
A39: LPG | B39: =SUM(C39:AU39) -> 0 | C39: ='Real values'!L125-'Real values'!L111 -> 0 | D39: ='Real values'!M125-'Real values'!M111 -> 0 | E39: ='Real values'!N125-'Real values'!N111 -> 0 | F39: ='Real values'!O125-'Real values'!O111 -> 0 | G39: ='Real values'!P125-'Real values'!P111 -> 0 | H39: ='Real values'!Q125-'Real values'!Q111 -> 0 | I39: ='Real values'!R125-'Real values'!R111 -> 0 | J39: ='Real values'!S125-'Real values'!S111 -> 0 | ... AP39: ='Real values'!AY125-'Real values'!AY111 -> 0 | AQ39: ='Real values'!BA125-'Real values'!BA111 -> 0 | AR39: ='Real values'!BB125-'Real values'!BB111 -> 0 | AS39: ='Real values'!BC125-'Real values'!BC111 -> 0 | AT39: ='Real values'!BD125-'Real values'!BD111 -> 0 | AU39: ='Real values'!BE125-'Real values'!BE111 -> 0 | AV39: ='Real values'!BF125-'Real values'!BF111 -> 0
A40: Light fuel oil | B40: =SUM(C40:AU40) -> 0 | C40: ='Real values'!L126-'Real values'!L112 -> 0 | D40: ='Real values'!M126-'Real values'!M112 -> 0 | E40: ='Real values'!N126-'Real values'!N112 -> 0 | F40: ='Real values'!O126-'Real values'!O112 -> 0 | G40: ='Real values'!P126-'Real values'!P112 -> 0 | H40: ='Real values'!Q126-'Real values'!Q112 -> 0 | I40: ='Real values'!R126-'Real values'!R112 -> 0 | J40: ='Real values'!S126-'Real values'!S112 -> 0 | ... AP40: ='Real values'!AY126-'Real values'!AY112 -> 0 | AQ40: ='Real values'!BA126-'Real values'!BA112 -> 0 | AR40: ='Real values'!BB126-'Real values'!BB112 -> 0 | AS40: ='Real values'!BC126-'Real values'!BC112 -> 0 | AT40: ='Real values'!BD126-'Real values'!BD112 -> 0 | AU40: ='Real values'!BE126-'Real values'!BE112 -> 0 | AV40: ='Real values'!BF126-'Real values'!BF112 -> 0
A41: Heavy fuel oil | B41: =SUM(C41:AU41) -> 0 | C41: ='Real values'!L127-'Real values'!L113 -> 0 | D41: ='Real values'!M127-'Real values'!M113 -> 0 | E41: ='Real values'!N127-'Real values'!N113 -> 0 | F41: ='Real values'!O127-'Real values'!O113 -> 0 | G41: ='Real values'!P127-'Real values'!P113 -> 0 | H41: ='Real values'!Q127-'Real values'!Q113 -> 0 | I41: ='Real values'!R127-'Real values'!R113 -> 0 | J41: ='Real values'!S127-'Real values'!S113 -> 0 | ... AP41: ='Real values'!AY127-'Real values'!AY113 -> 0 | AQ41: ='Real values'!BA127-'Real values'!BA113 -> 0 | AR41: ='Real values'!BB127-'Real values'!BB113 -> 0 | AS41: ='Real values'!BC127-'Real values'!BC113 -> 0 | AT41: ='Real values'!BD127-'Real values'!BD113 -> 0 | AU41: ='Real values'!BE127-'Real values'!BE113 -> 0 | AV41: ='Real values'!BF127-'Real values'!BF113 -> 0
A42: Geothermal | B42: =SUM(C42:AU42) -> 0 | C42: ='Real values'!L128-'Real values'!L114 -> 0 | D42: ='Real values'!M128-'Real values'!M114 -> 0 | E42: ='Real values'!N128-'Real values'!N114 -> 0 | F42: ='Real values'!O128-'Real values'!O114 -> 0 | G42: ='Real values'!P128-'Real values'!P114 -> 0 | H42: ='Real values'!Q128-'Real values'!Q114 -> 0 | I42: ='Real values'!R128-'Real values'!R114 -> 0 | J42: ='Real values'!S128-'Real values'!S114 -> 0 | ... AP42: ='Real values'!AY128-'Real values'!AY114 -> 0 | AQ42: ='Real values'!BA128-'Real values'!BA114 -> 0 | AR42: ='Real values'!BB128-'Real values'!BB114 -> 0 | AS42: ='Real values'!BC128-'Real values'!BC114 -> 0 | AT42: ='Real values'!BD128-'Real values'!BD114 -> 0 | AU42: ='Real values'!BE128-'Real values'!BE114 -> 0 | AV42: ='Real values'!BF128-'Real values'!BF114 -> 0
